Workbook

Sheet Instrucciones
B2: NETFLIX, INC. (NFLX) — MODELO DE VALORACION v1.0 (basado en Plantilla v1)
B3: Modelo multi-método (8 metodologías) con sensibilidades y reverse-DCF. Fecha de corte: 18-may-2026. Datos verificados contra 10-K FY2025 (filed 23-ene-2026) y 10-Q Q1 2026 (filed 17-abr-2026).
B5: ▶ QUICK START — los 4 pasos para usar la plantilla
B7: Paso 1 | C7: Edita la hoja Hipotesis (azul = inputs). Empieza por: Spot price, shares outstanding, WACC components (Rf, ERP, Beta, Kd), y tasa fiscal. El WACC se calcula automáticamente.
B8: Paso 2 | C8: Rellena la hoja Historico con datos reales de la empresa (5 años de P&L + Cash Flow + Balance, más el último parcial YTD si aplica). Todos los datos hardcodeados están en color azul. Los ratios y % se calculan solos.
B9: Paso 3 | C9: Vuelve a Hipotesis y ajusta las suposiciones de proyección: crecimiento por segmento (rows 30-32), margen operativo por segmento (rows 33-35), Capex/Rev y D&A/Rev (rows 39-42). 5 años de proyección, columnas C-G + Terminal en H.
B10: Paso 4 | C10: Revisa la hoja Modelo (8 metodologías + tabla de sensibilidades en cols L-R). Luego la hoja Reverse_DCF para ver qué pricea el mercado al spot actual. Termina con Conclusiones y Resumen escribiendo tu tesis.
B12: ▶ ESTRUCTURA DEL ARCHIVO — 8 hojas + esta guía
B14: Instrucciones | C14: Esta hoja (guía de uso). Borrar antes de entregar al cliente, mantener para iteración interna.
B15: Resumen | C15: Output ejecutivo. Recomendación, precio objetivo, drivers clave. Aquí pegas tu tesis cuando el modelo esté terminado. Contiene un chart de barras con los 8 precios implícitos.
B16: Hipotesis | C16: INPUTS CRÍTICOS. 5 secciones: (1) Mercado/Coste de capital + WACC, (2) Crecimiento por segmento × año, (3) Capex/D&A/SBC/WC ratios, (4) Valores terminales (g, exit multiples), (5) Inversiones estratégicas opcionales.
B17: Historico | C17: 5 años de financials + YTD parcial. Estructura: A=P&L, B=Cash Flow, C=Balance, D=Segmentos, E=KPIs trimestrales. Cada línea principal tiene su YoY% / margen INLINE debajo.
B18: Modelo | C18: Forecast operativo + 8 metodologías de valoración: 5 DCF (Gordon, H-Model, Exit EV/EBITDA, Exit EV/EBIT, Exit EV/Rev) + 3 NTM multiples (P/E, EV/EBITDA, EV/Rev). Incluye 4 tablas de sensibilidad embebidas (cols L-R).
B19: DuPont_WC | C19: Descomposición ROE/ROIC en 5 factores + análisis de working capital y cash conversion cycle. Para detectar si el ROE viene de margen, asset turnover o leverage.
B20: Reverse_DCF | C20: Dado el spot, qué assumptions implica el mercado (g terminal, WACC, EBIT margin, Capex/Rev, Revenue CAGR). 5 análisis closed-form, no iterativos.
B21: Conclusiones | C21: Narrativa cualitativa: tesis, debate bear/bull, escenarios, drivers ranked, riesgos, veredicto final con catalizadores a 12 meses.
B22: Fuentes | C22: Listado de fuentes citadas. CRÍTICO mantener fuentes primarias (filings) para auditabilidad.
B24: ▶ CÓDIGO DE COLORES Y CONVENCIONES
B26: Texto azul | C26: Input hardcoded — EDITAS tú
B27: Texto negro | C27: Cálculo (formula) — NO TOCAR
B28: Texto gris itálico | C28: Ratio inline (debajo de la línea principal — margen/growth %)
B29: Texto azul itálico | C29: Prompt — sustituir por contenido propio (Conclusiones/Resumen)
B30: Fondo amarillo (FFE699) | C30: Header de tabla o input clave
B31: Fondo verde (E2EFDA) | C31: Output relevante o resultado clave
B32: Fondo azul claro (DDEBF7) | C32: Subtotal o métrica de control
B33: Fondo rojo claro | C33: Advertencia o assumption importante
B35: ▶ LAS 8 METODOLOGÍAS — qué hace cada una y cuándo confiar en ella
B37: M1 — DCF Gordon Growth | C37: Suma PV de FCFF explícito (5 años, mid-year convention) + PV del valor terminal en perpetuidad FCFF_t × (1+g) / (WACC − g). El método más teórico pero EXTREMADAMENTE sensible a (WACC − g). Diferencias de 50bp en g cambian el precio 15-20%. Trade-off: pureza teórica vs sensibilidad.
B38: M2 — DCF H-Model (fade) | C38: Variante de Gordon donde el crecimiento decae linealmente de g_inicial (high-growth) a g_terminal durante n años. Más realista para compañías que aún están en fase de crecimiento. Útil cuando crees que el crecimiento no es estable sino transicional.
B39: M3 — DCF Exit EV/EBITDA | C39: PV del FCFF explícito + EV terminal calculado como múltiplo × EBITDA FY-final. Evita el problema de WACC−g del Gordon. Trade-off: el multiple aplicado debe ser DEFENDIBLE (comparable a peers o histórico de la empresa).
B40: M4 — DCF Exit EV/EBIT | C40: Igual que M3 pero usando EBIT × multiple. Más conservador (excluye D&A). Útil para empresas asset-heavy donde EBITDA infla la valoración por D&A alto.
B41: M5 — DCF Exit EV/Revenue | C41: Cross-check: EV terminal = revenue × P/S multiple. Útil para compañías sin profitability estable (early-stage, turnaround). En compañías maduras, es la metodología MÁS débil — no respeta unit economics.
B42: M6 — NTM P/E × FY27 EPS | C42: Equity = P/E × NI_FY27. Atajo basado en multiples NTM. Útil cuando tu peer set cotiza a un P/E claro y la convergencia es la tesis. Ignora el balance (cash, debt) — usar con cuidado en empresas net-cash.
B43: M7 — NTM EV/EBITDA × FY27 EBITDA | C43: EV = multiple × EBITDA_FY27. Bridge a equity con cash y debt actuales. Muy usado por sell-side. El más comparable cross-empresa porque normaliza capital structure.
B44: M8 — NTM EV/Revenue × FY27 Revenue | C44: Cross-check rapido. Útil en sectores con métricas operativas claras (SaaS, software). Combinar con tasa de growth — un multiple alto solo justifica con growth alto.
B46: Lectura | C46: La MEDIANA de las 8 metodologías es la referencia central (más robusta que el promedio frente a outliers). El RANGO (mín-máx) indica nivel de incertidumbre: si los 8 métodos rinden $80-$120, el precio justo es $100 ± 20%. Si rinden $50-$200, la valoración es altamente sensible a assumptions.
B48: ▶ CHECKLIST DE CALIDAD — ANTES DE PRESENTAR EL MODELO
C50: ✓ Todos los datos históricos referenciados a fuente primaria (memoria anual, reporte trimestral, etc.) — ver hoja Fuentes
C51: ✓ Tasa libre de riesgo y ERP actualizadas a fecha actual (Damodaran refresh mensual)
C52: ✓ Beta justificada: 5Y regression vs índice relevante O sectorial (Damodaran Industry Beta)
...

Sheet Resumen
B2: NETFLIX, INC. (NFLX) — RESUMEN EJECUTIVO DE VALORACION
B3: Modelo valoración integral · Fecha valoración: 18-may-2026 · Cierre FY: 31-dic (calendar year)
B5: 1. COMPANY SNAPSHOT / MARKET DATA (15-may-2026)
B6: Co-CEOs | C6: Ted Sarandos, Greg Peters | E6: Spot ($) | F6: =Hipotesis!$C$6 -> 87.02
B7: CFO | C7: Spencer Neumann | E7: Market Cap ($B) | F7: =Hipotesis!$C$21/1000 -> 366.59786
B8: Headquarters | C8: Los Gatos, CA, USA | E8: Enterprise Value ($B) | F8: =(Hipotesis!$C$21+Hipotesis!$C$14-Hipotesis!$C$15)/1000 -> 370.99986
B9: Fundada | C9: 1997 (DVD); streaming desde 2007 | E9: Shares Outstanding (M) | F9: =Hipotesis!$C$8 -> 4212.8
B10: Empleados (FY25) | C10: ~16,000 (TradingView) | E10: 52-week range | F10: $75.01 – $134.12 (post-split)
B11: Año fiscal | C11: Cierre 31-dic (calendar year) | E11: All-time high (close, post-split) | F11: $133.91 (30-jun-2025)
B12: Sector | C12: Streaming / Media / Entertainment | E12: P/E TTM | F12: ~27-46x (rango Trefis 27.6x / Robinhood 46.5x)
B13: Segmentos reportados | C13: 1 segmento operativo (streaming). Conceptuales: subscripción, ads, otros | E13: EPS TTM | F13: ~$2.55 (post-split, FY25)
B14: Ticker / Exchange | C14: NFLX / NASDAQ-GS | E14: Beta (5Y) | F14: =Hipotesis!$C$11 -> 1.25
B15: Index | C15: S&P 500, NASDAQ-100 | E15: Dividend Yield | F15: 0% (NFLX no paga dividendos)
B16: Stock split reciente | C16: 10-for-1 efectivo 17-nov-2025
B17: 2. Q1 2026 EARNINGS HIGHLIGHTS (trimestre cerrado 31-mar-2026; filing 17-abr-2026)
B18: Revenue Q1 2026 | C18: $12,250M | E18: +16.2% YoY (vs $10,543M Q1 2025)
B19: Operating Income Q1 2026 | C19: $3,957M | E19: Op margin 32.3% (vs guide 32.1%)
B20: Net Income Q1 2026 | C20: $5,283M | E20: Diluted EPS $1.23 — INCLUYE $2.85bn one-off (Other income)
B21: Paid memberships (Q4 2025 último report) | C21: >325M | E21: Q1 2026 ya no reporta member adds (mgmt decision)
B22: Advertising revenue (Q1 run-rate) | C22: ~$2.0-2.5bn anualizado | E22: Mgmt guía ~2x FY26 (vs >$1.5bn FY25)
B23: Engagement | C23: ~2h+ per member/day | E23: Estable; clave para retención + ad ROI
B24: Content additions FY25 | C24: $17.1bn | E24: Content amortization $16.4bn (alineadas)
B25: Content obligations no reconocidas BS | C25: $18.4bn | E25: Compromisos operativos (no deuda)
B26: PP&E Capex Q1 2026 | C26: $196M | E26: Capex clásico minimal (1.5% rev)
B27: FCF Q1 2026 | C27: $5,094M | E27: OCF $5,290M − Capex $196M
B28: Buyback Q1 2026 | C28: $1,271M | E28: Bajo vs Q1 2025 ($3.5bn) — preserve cash en bid WBD (fallido)
B29: Dividends Q1 2026 | C29: $0 | E29: No dividend policy
B30: ⚠ Operación Warner Bros. (WBD) | C30: NETFLIX SE RETIRÓ 26-feb-2026 | E30: Paramount Skydance ganó @ $31/share ($110.9bn). Modelo es STANDALONE.
B31: Dividends Q3 | C31: $6.2B
B33: 3. 5-YEAR HISTORICAL FINANCIALS (FY21-FY25, $mm except per-share / ratios)
B34: Metric | C34: FY21 | D34: FY22 | E34: FY23 | F34: FY24 | G34: FY25
B35: Revenue ($mm) | C35: 29698 | D35: 31616 | E35: 33723 | F35: 39001 | G35: 45183
B36: YoY growth | C36: +18.8% | D36: +6.5% | E36: +6.7% | F36: +15.6% | G36: +15.8%
B37: Operating Income | C37: 6195 | D37: 5633 | E37: 6954 | F37: 10418 | G37: 13327
B38: Operating margin | C38: 20.9% | D38: 17.8% | E38: 20.6% | F38: 26.7% | G38: 29.5%
B39: Net Income | C39: 5116 | D39: 4492 | E39: 5408 | F39: 8712 | G39: 10981
B40: Diluted EPS (post-split) | C40: 1.13 | D40: 1 | E40: 1.22 | F40: 2 | G40: 2.55
B41: OCF | C41: 393 | D41: 2026 | E41: 7274 | F41: 7361 | G41: 10149
B42: PP&E Capex | C42: -525 | D42: -408 | E42: -349 | F42: -440 | G42: -688
B43: Free Cash Flow | C43: -132 | D43: 1619 | E43: 6925 | F43: 6921 | G43: 9461
...

Sheet Hipotesis
B1: NETFLIX, INC. (NFLX) — HIPOTESIS Y SUPUESTOS DE VALORACION
B2: LEYENDA: | C2: Input (hardcoded) | D2: Driver clave | E2: Formula | F2: Link a otra hoja | G2: Resultado/output
B4: 1. MERCADO Y COSTE DE CAPITAL
B5: Concepto | C5: Valor | D5: Fuente / Nota
B6: Spot price ($) | C6: 87.02 | D6: Source: Morningstar/Macrotrends close 15-may-2026; 10:1 stock split efectivo 17-nov-2025
B7: Diluted shares outstanding (M) | C7: 4298.4 | D7: Source: NFLX 10-Q Q1 2026 (period 31-mar-2026), Statements of Operations, Note 2 EPS; filed 17-abr-2026
B8: Shares outstanding actual (M) | C8: 4212.8 | D8: Source: NFLX 10-Q Q1 2026 cover, shares outstanding as of 31-mar-2026: 4,212,794,271
B9: Risk-free rate (10Y bono soberano, %) | C9: 0.0454 | D9: Source: FRED DGS10 (10Y UST), mid-may-2026 ~4.50-4.55% range
B10: Equity Risk Premium implícita (%) | C10: 0.0423 | D10: Source: Damodaran ERP 2026 Edition (jan-2026 implied ERP S&P500). Ref: https://pages.stern.nyu.edu/~adamodar/
B11: Beta (5Y o regression sectorial) | C11: 1.25 | D11: Source: Yahoo Finance / 5Y monthly regression vs S&P500 (rango histórico 1.15-1.40); usado punto medio
B12: Pre-tax cost of debt (%) | C12: 0.0525 | D12: Source: NFLX corporate bonds (5Y senior unsec) yielding ~5.0-5.5%, BBB- rating (S&P/Moody) + ~70bp spread over 10Y UST
B13: Effective tax rate (%) | C13: 0.2 | D13: Source: NFLX 10-K FY2025 + 10-Q Q1 2026; tax rate efectivo FY24=18.0%, FY25=~20.0%, Q1 2026=19.3%. Use 20% baseline.
B14: Total Debt ($mm, book) | C14: 13464 | D14: Source: NFLX 10-K FY2025 BS, long-term debt total $13,464M (filed 23-ene-2026)
B15: Cash + STI ($mm, book) | C15: 9062 | D15: Source: NFLX 10-K FY2025 BS, cash + short-term investments $9,062M
B16: Equity & other investments ($mm) | C16: 0 | D16: Source: NFLX no tiene equity investments materiales en BS (no incluye stakes estratégicos como MSFT/OpenAI)
B18: WACC computado
B19: Cost of equity Ke = Rf + Beta × ERP | C19: =Hipotesis!$C$9 + Hipotesis!$C$11*Hipotesis!$C$10 -> 0.098275
B20: After-tax cost of debt Kd = Kd*(1-T) | C20: =Hipotesis!$C$12 * (1 - Hipotesis!$C$13) -> 0.042
B21: Market cap = Spot × Shares ($mm) | C21: =Hipotesis!$C$6 * Hipotesis!$C$8 -> 366597.86
B22: Total enterprise capital = MC + Debt | C22: =Hipotesis!$C$21 + Hipotesis!$C$14 -> 380061.86
B23: Weight equity E/V | C23: =Hipotesis!$C$21 / Hipotesis!$C$22 -> 0.96457419
B24: Weight debt D/V | C24: =Hipotesis!$C$14 / Hipotesis!$C$22 -> 0.035425812
B25: WACC = E/V × Ke + D/V × Kd*(1-T) | C25: =Hipotesis!$C$23*Hipotesis!$C$19 + Hipotesis!$C$24*Hipotesis!$C$20 -> 0.096281412
B28: 2. CRECIMIENTO POR SEGMENTO (forecast horizon = años fiscales junio)
B29: Segmento / Driver | C29: FY2026E | D29: FY2027E | E29: FY2028E | F29: FY2029E | G29: FY2030E | H29: Terminal
B30: S1 — Suscripción core (membership) | C30: 0.1 | D30: 0.08 | E30: 0.07 | F30: 0.06 | G30: 0.05 | H30: 0.03 | J30: Q4 2025: 325M paid members. FY25 +16%. Paid sharing tailwind madura. Pricing power compensa parcialmente. Mar-2026 price hikes ayudan FY26.
B31: S2 — Publicidad (ad tier) | C31: 1 | D31: 0.6 | E31: 0.4 | F31: 0.25 | G31: 0.15 | H31: 0.05 | J31: Source: Shareholder Letter Q4 2025 — ad revenue >$1.5bn FY25, mgmt guía ~2x en FY26. Fade gradual con maduración del inventario y CPMs
B32: S3 — Otros (games, live events, theatrical, partnerships) | C32: 0.5 | D32: 0.4 | E32: 0.3 | F32: 0.2 | G32: 0.15 | H32: 0.05 | J32: Source: Mgmt commentary FY26 — expansión categorías (games, live events, video podcasts, "Narnia" theatrical 2026). Base pequeña, alto growth %
B33: S1 op margin % | C33: 0.33 | D33: 0.34 | E33: 0.35 | F33: 0.355 | G33: 0.36 | H33: 0.36 | J33: Subscription margin expandiendo por escala. Implícito vs op margin consolidado FY25 29.5% (incluye ads en fase inversión)
B34: S2 op margin % | C34: 0.05 | D34: 0.12 | E34: 0.18 | F34: 0.23 | G34: 0.28 | H34: 0.3 | J34: Negocio publicitario en fase inversión (ad-tech, ventas, medición). Margen escala con fill rate, CPMs, partners. Terminal vs peers CTV ~25-30%
B35: S3 op margin % | C35: 0.05 | D35: 0.1 | E35: 0.12 | F35: 0.15 | G35: 0.18 | H35: 0.2 | J35: Games + live events + theatrical: heavy upfront investment, margin maduración lenta. Conservador.
B37: 3. CAPEX, D&A Y CAPITAL ALLOCATION
B38: Driver | C38: FY2026E | D38: FY2027E | E38: FY2028E | F38: FY2029E | G38: FY2030E | H38: Terminal
B39: Capex / Revenue % | C39: 0.015 | D39: 0.015 | E39: 0.015 | F39: 0.014 | G39: 0.014 | H39: 0.013 | J39: PP&E capex únicamente (clásico). Contenido va vía OCF (amortizado en cost of revenues). FY25 actual 1.5%; estable.
B40: D&A / Revenue % | C40: 0.008 | D40: 0.008 | E40: 0.008 | F40: 0.008 | G40: 0.008 | H40: 0.008 | J40: PP&E D&A únicamente (~$99M Q1 2026 = ~$396M anualizado / $50bn rev ~ 0.8%). Content amortization YA está dentro de cost of revenues (FY25: $16.4bn)
B41: SBC / Revenue % | C41: 0.012 | D41: 0.012 | E41: 0.012 | F41: 0.012 | G41: 0.012 | H41: 0.012 | J41: Source: 10-Q Q1 2026 SBC $140M / Q rev $12.25bn ~ 1.15%. NFLX SBC moderada vs tech peers
B42: ΔWC / Revenue % | C42: -0.005 | D42: -0.005 | E42: -0.005 | F42: 0 | G42: 0 | H42: 0 | J42: NFLX subscription model: cobros adelantados → WC favorable (deferred revenue +$32M Q1 2026). Pequeño beneficio.
B43: Buybacks / FCF % | C43: 0.85 | D43: 0.85 | E43: 0.85 | F43: 0.8 | G43: 0.8 | H43: 0.75 | J43: FY25 96.5% FCF. Mgmt ha mantenido buybacks como vehículo principal de capital return. Sin dividendos.
B45: 4. VALORES TERMINALES (TV) Y CROSS-CHECKS
B46: Concepto | C46: Valor | D46: Justificación
...

Sheet Historico
B1: NETFLIX, INC. (NFLX) — HISTORICO FINANCIERO (FY2021 a FY2025 + Q1 2026)
B2: LEYENDA: | C2: Input (hardcoded) | D2: Cálculo (margen/growth) | E2: Inline ratio
B4: $ millions | C4: FY2021 | D4: FY2022 | E4: FY2023 | F4: FY2024 | G4: FY2025 | H4: Q1 2026
B5: A. CUENTA DE RESULTADOS ($mm except per-share)
B6: Revenue | C6: 29698 | D6: 31616 | E6: 33723 | F6: 39001 | G6: 45183 | H6: 12250 | I6: Source: NFLX 10-K FY2025 + 10-Q Q1 2026; CAGR FY21-FY25 = 11.0%
B7: Revenue YoY % | C7: n/a | D7: =D6/C6-1 -> 0.064583474 | E7: =E6/D6-1 -> 0.066643472 | F7: =F6/E6-1 -> 0.15651039 | G7: =G6/F6-1 -> 0.15850876 | H7: ytd | I7: CAGR FY21-FY25 ≈ 13.8%
B8: Cost of revenue | C8: 17332 | D8: 19169 | E8: 19715 | F8: 21034 | G8: 22045 | H8: 5888 | I8: Source: 10-K FY2025 + 10-Q Q1 2026; CoR incluye content amortization + delivery costs. FY21-FY24 estimados; FY25/Q1 2026 directos
B9: Cost of revenue / Revenue % | C9: =C8/C6 -> 0.58360832 | D9: =D8/D6 -> 0.60630693 | E9: =E8/E6 -> 0.58461584 | F9: =F8/F6 -> 0.5393195 | G9: =G8/G6 -> 0.48790474 | H9: =H8/H6 -> 0.48065306 | I9: Subiendo por [Driver de crecimiento] infra
B10: Gross profit | C10: 12366 | D10: 12447 | E10: 14008 | F10: 17967 | G10: 23138 | H10: 6362
B11: Gross margin % | C11: =C10/C6 -> 0.41639168 | D11: =D10/D6 -> 0.39369307 | E11: =E10/E6 -> 0.41538416 | F11: =F10/F6 -> 0.4606805 | G11: =G10/G6 -> 0.51209526 | H11: =H10/H6 -> 0.51934694 | I11: 69-70% [Plataforma cloud] GM en Último trimestre
B12: Technology and development (R&D equivalent) | C12: 2273 | D12: 2711 | E12: 2674 | F12: 2925 | G12: 3464 | H12: 960 | I12: Tech & dev (R&D equivalent) per 10-K; Q1 2026 $960M; FY21-FY24 estimados from filings
B13: R&D / Revenue % | C13: =C12/C6 -> 0.076537141 | D13: =D12/D6 -> 0.085747723 | E13: =E12/E6 -> 0.079293064 | F13: =F12/F6 -> 0.074998077 | G13: =G12/G6 -> 0.076666003 | H13: =H12/H6 -> 0.078367347 | I13: Estable ~12% — leverage del modelo
B14: S&M | C14: 2545 | D14: 2530 | E14: 2554 | F14: 2884 | G14: 3057 | H14: 842 | I14: Sales & marketing per 10-K; Q1 2026 $842M directo
B15: S&M / Revenue % | C15: =C14/C6 -> 0.085696006 | D15: =D14/D6 -> 0.080022773 | E15: =E14/E6 -> 0.075734662 | F15: =F14/F6 -> 0.073946822 | G15: =G14/G6 -> 0.06765819 | H15: =H14/H6 -> 0.068734694 | I15: Bajando con scale (de 12% → 9%)
B16: G&A | C16: 1351 | D16: 1572 | E16: 1626 | F16: 1741 | G16: 2245 | H16: 603 | I16: G&A per 10-K; Q1 2026 $603M directo
B17: G&A / Revenue % | C17: =C16/C6 -> 0.045491279 | D17: =D16/D6 -> 0.04972166 | E17: =E16/E6 -> 0.048216351 | F17: =F16/F6 -> 0.044639881 | G17: =G16/G6 -> 0.049686829 | H17: =H16/H6 -> 0.04922449 | I17: ~3% estable
B18: Operating income | C18: 6195 | D18: 5633 | E18: 6954 | F18: 10418 | G18: 13327 | H18: 3957 | I18: Source: NFLX 10-K FY2025 + 10-Q Q1 2026 directo. Op margin FY25 29.5%, Q1 2026 32.3%
B19: Operating margin % | C19: =C18/C6 -> 0.20859991 | D19: =D18/D6 -> 0.17816928 | E19: =E18/E6 -> 0.20620941 | F19: =F18/F6 -> 0.26712136 | G19: =G18/G6 -> 0.29495607 | H19: =H18/H6 -> 0.32302041 | I19: 📈 +330bp FY21-FY25, +200bp más en 9M parcial (47%)
B20: Op income YoY % | C20: n/a | D20: =D18/C18-1 -> -0.090718321 | E20: =E18/D18-1 -> 0.23451092 | F20: =F18/E18-1 -> 0.49813057 | G20: =G18/F18-1 -> 0.27922826 | H20: ytd
B21: Other income (expense), net | C21: 411 | D21: -353 | E21: 56 | F21: 869 | G21: 553 | H21: 2590 | I21: NB Q1 2026: $2,852M en "Interest and other income (expense)" — ONE-OFF (FX gains/divest gains/hedging). El NI ajustado excluyendo este ítem ~$3,1bn
B22: Income before taxes | C22: 6606 | D22: 5280 | E22: 7010 | F22: 11287 | G22: 13880 | H22: 6547
B23: Provision for income taxes | C23: 1490 | D23: 788 | E23: 1602 | F23: 2575 | G23: 2899 | H23: 1264
B24: Effective tax rate | C24: =C23/C22 -> 0.22555253 | D24: =D23/D22 -> 0.14924242 | E24: =E23/E22 -> 0.22853067 | F24: =F23/F22 -> 0.22813857 | G24: =G23/G22 -> 0.20886167 | H24: =H23/H22 -> 0.19306553 | I24: 18% FY24-FY25, ligero uptick Último trimestre
B25: Net income | C25: 5116 | D25: 4492 | E25: 5408 | F25: 8712 | G25: 10981 | H25: 5283 | I25: Source: 10-K FY2025 + 10-Q Q1 2026. Q1 2026 incluye $2.85bn one-off (Other income)
B26: Net margin % | C26: =C25/C6 -> 0.17226749 | D26: =D25/D6 -> 0.14207996 | E26: =E25/E6 -> 0.16036533 | F26: =F25/F6 -> 0.22337889 | G26: =G25/G6 -> 0.24303388 | H26: =H25/H6 -> 0.43126531 | I26: ~36% — quality of earnings alto
B27: Net income YoY % | C27: n/a | D27: =D25/C25-1 -> -0.12197029 | E27: =E25/D25-1 -> 0.20391808 | F27: =F25/E25-1 -> 0.61094675 | G27: =G25/F25-1 -> 0.26044536 | H27: ytd
B28: Diluted EPS ($) | C28: 1.13 | D28: 1 | E28: 1.22 | F28: 2 | G28: 2.55 | H28: 1.23 | I28: EPS post-split 10:1 (efectivo 17-nov-2025). Historical retroactively adjusted. Q1 2026 inflado por one-off
B29: Diluted EPS YoY % | C29: n/a | D29: =D28/C28-1 -> -0.11504425 | E29: =E28/D28-1 -> 0.22 | F29: =F28/E28-1 -> 0.63934426 | G29: =G28/F28-1 -> 0.275 | H29: ytd | I29: Buybacks ayudan ~50bp/año al EPS growth
B30: Diluted shares (M) | C30: 4520 | D30: 4500 | E30: 4450 | F30: 4368 | G30: 4318 | H30: 4298.4 | I30: Diluted weighted-avg shares post-10:1 split. Buybacks reducen count
B32: B. CASH FLOW ($mm)
B33: Net cash from operations (OCF) | C33: 393 | D33: 2026 | E33: 7274 | F33: 7361 | G33: 10149 | H33: 5290 | I33: Source: NFLX 10-K + 10-Q Q1 2026 Cash Flow Statement. OCF YA NETO de pagos de contenido
B34: OCF / Revenue % | C34: =C33/C6 -> 0.013233214 | D34: =D33/D6 -> 0.064081478 | E34: =E33/E6 -> 0.21569848 | F34: =F33/F6 -> 0.18873875 | G34: =G33/G6 -> 0.22461988 | H34: =H33/H6 -> 0.43183673 | I34: ~48% — cash conversion alta
B35: OCF YoY % | C35: n/a | D35: =D33/C33-1 -> 4.1552163 | E35: =E33/D33-1 -> 2.5903258 | F35: =F33/E33-1 -> 0.011960407 | G35: =G33/F33-1 -> 0.37875289 | H35: ytd
B36: Capex (Additions to P&E) | C36: 525 | D36: 408 | E36: 349 | F36: 440 | G36: 688 | H36: 196 | I36: PP&E capex únicamente (no contenido). FY25 1.5% revenue
B37: Capex / Revenue % | C37: =C36/C6 -> 0.017677958 | D37: =D36/D6 -> 0.012904858 | E37: =E36/E6 -> 0.01034902 | F37: =F36/F6 -> 0.011281762 | G37: =G36/G6 -> 0.015226966 | H37: =H36/H6 -> 0.016 | I37: 📈 12% → 23% TTM → 33% 9M parcial (inversión productiva)
B38: Capex YoY % | C38: n/a | D38: =D36/C36-1 -> -0.22285714 | E38: =E36/D36-1 -> -0.14460784 | F38: =F36/E36-1 -> 0.26074499 | G38: =G36/F36-1 -> 0.56363636 | H38: ytd | I38: +213% acumulado FY21-FY25
B39: FCF simple = OCF − Capex | C39: -132 | D39: 1619 | E39: 6925 | F39: 6921 | G39: 9461 | H39: 5094 | I39: FCF simple = OCF - PP&E capex. Para NFLX el contenido YA está en OCF (a diferencia de empresas asset-heavy donde contenido sería capex)
B40: FCF / Revenue % | C40: =C39/C6 -> -0.0044447438 | D40: =D39/D6 -> 0.051208249 | E40: =E39/E6 -> 0.20534946 | F40: =F39/F6 -> 0.17745699 | G40: =G39/G6 -> 0.20939291 | H40: =H39/H6 -> 0.41583673 | I40: Bajando 33% → 25% por capex inversión
B41: FCF / Net Income % | C41: =C39/C25 -> -0.025801407 | D41: =D39/D25 -> 0.36041852 | E41: =E39/E25 -> 1.2805104 | F41: =F39/F25 -> 0.79442149 | G41: =G39/G25 -> 0.86157909 | H41: =H39/H25 -> 0.96422487 | I41: <70% confirma que la depreciación NO captura todo el outflow
B42: FCF YoY % | C42: n/a | D42: =D39/C39-1 -> -13.265152 | E42: =E39/D39-1 -> 3.2773317 | F42: =F39/E39-1 -> -0.00057761733 | G42: =G39/F39-1 -> 0.36699899 | H42: ytd
...

Sheet Modelo
B1: NETFLIX, INC. (NFLX) — MODELO OPERATIVO + FCFF + VALORACION (segmentado conceptual, FY26-FY30)
B2: LEYENDA: | C2: Input (azul) | D2: Cálculo (negro) | E2: Inline ratio | F2: Total (negrita) | G2: Terminal
B4: $ millions | C4: FY2026E | D4: FY2027E | E4: FY2028E | F4: FY2029E | G4: FY2030E | H4: Terminal
L5: Tabla A — Precio (Gordon DCF) vs WACC × g_terminal
B6: A. PROYECCION DE INGRESOS POR SEGMENTO
B7: S1 Suscripcion core revenue | C7: =Historico!G74*(1+Hipotesis!C30) -> 47960 | D7: =C7*(1+Hipotesis!D30) -> 51796.8 | E7: =D7*(1+Hipotesis!E30) -> 55422.576 | F7: =E7*(1+Hipotesis!F30) -> 58747.931 | G7: =F7*(1+Hipotesis!G30) -> 61685.327 | H7: =G7*(1+Hipotesis!H30) -> 63535.887 | L7: WACC ↓ \ g → | M7: 0.02 | N7: 0.025 | O7: 0.03 | P7: 0.035 | Q7: 0.04
B8: S1 Suscripcion core — revenue YoY % | C8: =C7/Historico!G74-1 -> 0.1 | D8: =D7/C7-1 -> 0.08 | E8: =E7/D7-1 -> 0.07 | F8: =F7/E7-1 -> 0.06 | G8: =G7/F7-1 -> 0.05 | H8: =H7/G7-1 -> 0.03 | L8: 0.075 | M8: =((C33/(1+$L$8)^0.5 + D33/(1+$L$8)^1.5 + E33/(1+$L$8)^2.5 + F33/(1+$L$8)^3.5 + G33/(1+$L$8)^4.5)+(G33*(1+M$7)/($L$8-M$7))/(1+$L$8)^5+Hipotesis!$C$15+Hipotesis!$C$16-Hipotesis!$C$14)/Hipotesis!$C$8 -> 74.753654 | N8: =((C33/(1+$L$8)^0.5 + D33/(1+$L$8)^1.5 + E33/(1+$L$8)^2.5 + F33/(1+$L$8)^3.5 + G33/(1+$L$8)^4.5)+(G33*(1+N$7)/($L$8-N$7))/(1+$L$8)^5+Hipotesis!$C$15+Hipotesis!$C$16-Hipotesis!$C$14)/Hipotesis!$C$8 -> 81.069806 | O8: =((C33/(1+$L$8)^0.5 + D33/(1+$L$8)^1.5 + E33/(1+$L$8)^2.5 + F33/(1+$L$8)^3.5 + G33/(1+$L$8)^4.5)+(G33*(1+O$7)/($L$8-O$7))/(1+$L$8)^5+Hipotesis!$C$15+Hipotesis!$C$16-Hipotesis!$C$14)/Hipotesis!$C$8 -> 88.789548 | P8: =((C33/(1+$L$8)^0.5 + D33/(1+$L$8)^1.5 + E33/(1+$L$8)^2.5 + F33/(1+$L$8)^3.5 + G33/(1+$L$8)^4.5)+(G33*(1+P$7)/($L$8-P$7))/(1+$L$8)^5+Hipotesis!$C$15+Hipotesis!$C$16-Hipotesis!$C$14)/Hipotesis!$C$8 -> 98.439225 | Q8: =((C33/(1+$L$8)^0.5 + D33/(1+$L$8)^1.5 + E33/(1+$L$8)^2.5 + F33/(1+$L$8)^3.5 + G33/(1+$L$8)^4.5)+(G33*(1+Q$7)/($L$8-Q$7))/(1+$L$8)^5+Hipotesis!$C$15+Hipotesis!$C$16-Hipotesis!$C$14)/Hipotesis!$C$8 -> 110.84595
B9: S2 Publicidad revenue | C9: =Historico!G75*(1+Hipotesis!C31) -> 3000 | D9: =C9*(1+Hipotesis!D31) -> 4800 | E9: =D9*(1+Hipotesis!E31) -> 6720 | F9: =E9*(1+Hipotesis!F31) -> 8400 | G9: =F9*(1+Hipotesis!G31) -> 9660 | H9: =G9*(1+Hipotesis!H31) -> 10143 | L9: 0.085 | M9: =((C33/(1+$L$9)^0.5 + D33/(1+$L$9)^1.5 + E33/(1+$L$9)^2.5 + F33/(1+$L$9)^3.5 + G33/(1+$L$9)^4.5)+(G33*(1+M$7)/($L$9-M$7))/(1+$L$9)^5+Hipotesis!$C$15+Hipotesis!$C$16-Hipotesis!$C$14)/Hipotesis!$C$8 -> 62.867657 | N9: =((C33/(1+$L$9)^0.5 + D33/(1+$L$9)^1.5 + E33/(1+$L$9)^2.5 + F33/(1+$L$9)^3.5 + G33/(1+$L$9)^4.5)+(G33*(1+N$7)/($L$9-N$7))/(1+$L$9)^5+Hipotesis!$C$15+Hipotesis!$C$16-Hipotesis!$C$14)/Hipotesis!$C$8 -> 67.159418 | O9: =((C33/(1+$L$9)^0.5 + D33/(1+$L$9)^1.5 + E33/(1+$L$9)^2.5 + F33/(1+$L$9)^3.5 + G33/(1+$L$9)^4.5)+(G33*(1+O$7)/($L$9-O$7))/(1+$L$9)^5+Hipotesis!$C$15+Hipotesis!$C$16-Hipotesis!$C$14)/Hipotesis!$C$8 -> 72.2315 | P9: =((C33/(1+$L$9)^0.5 + D33/(1+$L$9)^1.5 + E33/(1+$L$9)^2.5 + F33/(1+$L$9)^3.5 + G33/(1+$L$9)^4.5)+(G33*(1+P$7)/($L$9-P$7))/(1+$L$9)^5+Hipotesis!$C$15+Hipotesis!$C$16-Hipotesis!$C$14)/Hipotesis!$C$8 -> 78.317999 | Q9: =((C33/(1+$L$9)^0.5 + D33/(1+$L$9)^1.5 + E33/(1+$L$9)^2.5 + F33/(1+$L$9)^3.5 + G33/(1+$L$9)^4.5)+(G33*(1+Q$7)/($L$9-Q$7))/(1+$L$9)^5+Hipotesis!$C$15+Hipotesis!$C$16-Hipotesis!$C$14)/Hipotesis!$C$8 -> 85.757052
B10: S2 Publicidad — revenue YoY % | C10: =C9/Historico!G75-1 -> 1 | D10: =D9/C9-1 -> 0.6 | E10: =E9/D9-1 -> 0.4 | F10: =F9/E9-1 -> 0.25 | G10: =G9/F9-1 -> 0.15 | H10: =H9/G9-1 -> 0.05 | L10: 0.0912 | M10: =((C33/(1+$L$10)^0.5 + D33/(1+$L$10)^1.5 + E33/(1+$L$10)^2.5 + F33/(1+$L$10)^3.5 + G33/(1+$L$10)^4.5)+(G33*(1+M$7)/($L$10-M$7))/(1+$L$10)^5+Hipotesis!$C$15+Hipotesis!$C$16-Hipotesis!$C$14)/Hipotesis!$C$8 -> 57.187006 | N10: =((C33/(1+$L$10)^0.5 + D33/(1+$L$10)^1.5 + E33/(1+$L$10)^2.5 + F33/(1+$L$10)^3.5 + G33/(1+$L$10)^4.5)+(G33*(1+N$7)/($L$10-N$7))/(1+$L$10)^5+Hipotesis!$C$15+Hipotesis!$C$16-Hipotesis!$C$14)/Hipotesis!$C$8 -> 60.658079 | O10: =((C33/(1+$L$10)^0.5 + D33/(1+$L$10)^1.5 + E33/(1+$L$10)^2.5 + F33/(1+$L$10)^3.5 + G33/(1+$L$10)^4.5)+(G33*(1+O$7)/($L$10-O$7))/(1+$L$10)^5+Hipotesis!$C$15+Hipotesis!$C$16-Hipotesis!$C$14)/Hipotesis!$C$8 -> 64.696321 | P10: =((C33/(1+$L$10)^0.5 + D33/(1+$L$10)^1.5 + E33/(1+$L$10)^2.5 + F33/(1+$L$10)^3.5 + G33/(1+$L$10)^4.5)+(G33*(1+P$7)/($L$10-P$7))/(1+$L$10)^5+Hipotesis!$C$15+Hipotesis!$C$16-Hipotesis!$C$14)/Hipotesis!$C$8 -> 69.453111 | Q10: =((C33/(1+$L$10)^0.5 + D33/(1+$L$10)^1.5 + E33/(1+$L$10)^2.5 + F33/(1+$L$10)^3.5 + G33/(1+$L$10)^4.5)+(G33*(1+Q$7)/($L$10-Q$7))/(1+$L$10)^5+Hipotesis!$C$15+Hipotesis!$C$16-Hipotesis!$C$14)/Hipotesis!$C$8 -> 75.138961
B11: S3 Otros (games/live/licensing) revenue | C11: =Historico!G76*(1+Hipotesis!C32) -> 124.5 | D11: =C11*(1+Hipotesis!D32) -> 174.3 | E11: =D11*(1+Hipotesis!E32) -> 226.59 | F11: =E11*(1+Hipotesis!F32) -> 271.908 | G11: =F11*(1+Hipotesis!G32) -> 312.6942 | H11: =G11*(1+Hipotesis!H32) -> 328.32891 | L11: 0.1 | M11: =((C33/(1+$L$11)^0.5 + D33/(1+$L$11)^1.5 + E33/(1+$L$11)^2.5 + F33/(1+$L$11)^3.5 + G33/(1+$L$11)^4.5)+(G33*(1+M$7)/($L$11-M$7))/(1+$L$11)^5+Hipotesis!$C$15+Hipotesis!$C$16-Hipotesis!$C$14)/Hipotesis!$C$8 -> 50.649023 | N11: =((C33/(1+$L$11)^0.5 + D33/(1+$L$11)^1.5 + E33/(1+$L$11)^2.5 + F33/(1+$L$11)^3.5 + G33/(1+$L$11)^4.5)+(G33*(1+N$7)/($L$11-N$7))/(1+$L$11)^5+Hipotesis!$C$15+Hipotesis!$C$16-Hipotesis!$C$14)/Hipotesis!$C$8 -> 53.289589 | O11: =((C33/(1+$L$11)^0.5 + D33/(1+$L$11)^1.5 + E33/(1+$L$11)^2.5 + F33/(1+$L$11)^3.5 + G33/(1+$L$11)^4.5)+(G33*(1+O$7)/($L$11-O$7))/(1+$L$11)^5+Hipotesis!$C$15+Hipotesis!$C$16-Hipotesis!$C$14)/Hipotesis!$C$8 -> 56.30738 | P11: =((C33/(1+$L$11)^0.5 + D33/(1+$L$11)^1.5 + E33/(1+$L$11)^2.5 + F33/(1+$L$11)^3.5 + G33/(1+$L$11)^4.5)+(G33*(1+P$7)/($L$11-P$7))/(1+$L$11)^5+Hipotesis!$C$15+Hipotesis!$C$16-Hipotesis!$C$14)/Hipotesis!$C$8 -> 59.789446 | Q11: =((C33/(1+$L$11)^0.5 + D33/(1+$L$11)^1.5 + E33/(1+$L$11)^2.5 + F33/(1+$L$11)^3.5 + G33/(1+$L$11)^4.5)+(G33*(1+Q$7)/($L$11-Q$7))/(1+$L$11)^5+Hipotesis!$C$15+Hipotesis!$C$16-Hipotesis!$C$14)/Hipotesis!$C$8 -> 63.851857
B12: S3 Otros — revenue YoY % | C12: =C11/Historico!G76-1 -> 0.5 | D12: =D11/C11-1 -> 0.4 | E12: =E11/D11-1 -> 0.3 | F12: =F11/E11-1 -> 0.2 | G12: =G11/F11-1 -> 0.15 | H12: =H11/G11-1 -> 0.05 | L12: 0.11 | M12: =((C33/(1+$L$12)^0.5 + D33/(1+$L$12)^1.5 + E33/(1+$L$12)^2.5 + F33/(1+$L$12)^3.5 + G33/(1+$L$12)^4.5)+(G33*(1+M$7)/($L$12-M$7))/(1+$L$12)^5+Hipotesis!$C$15+Hipotesis!$C$16-Hipotesis!$C$14)/Hipotesis!$C$8 -> 44.786981 | N12: =((C33/(1+$L$12)^0.5 + D33/(1+$L$12)^1.5 + E33/(1+$L$12)^2.5 + F33/(1+$L$12)^3.5 + G33/(1+$L$12)^4.5)+(G33*(1+N$7)/($L$12-N$7))/(1+$L$12)^5+Hipotesis!$C$15+Hipotesis!$C$16-Hipotesis!$C$14)/Hipotesis!$C$8 -> 46.784384 | O12: =((C33/(1+$L$12)^0.5 + D33/(1+$L$12)^1.5 + E33/(1+$L$12)^2.5 + F33/(1+$L$12)^3.5 + G33/(1+$L$12)^4.5)+(G33*(1+O$7)/($L$12-O$7))/(1+$L$12)^5+Hipotesis!$C$15+Hipotesis!$C$16-Hipotesis!$C$14)/Hipotesis!$C$8 -> 49.031463 | P12: =((C33/(1+$L$12)^0.5 + D33/(1+$L$12)^1.5 + E33/(1+$L$12)^2.5 + F33/(1+$L$12)^3.5 + G33/(1+$L$12)^4.5)+(G33*(1+P$7)/($L$12-P$7))/(1+$L$12)^5+Hipotesis!$C$15+Hipotesis!$C$16-Hipotesis!$C$14)/Hipotesis!$C$8 -> 51.578152 | Q12: =((C33/(1+$L$12)^0.5 + D33/(1+$L$12)^1.5 + E33/(1+$L$12)^2.5 + F33/(1+$L$12)^3.5 + G33/(1+$L$12)^4.5)+(G33*(1+Q$7)/($L$12-Q$7))/(1+$L$12)^5+Hipotesis!$C$15+Hipotesis!$C$16-Hipotesis!$C$14)/Hipotesis!$C$8 -> 54.488655
B13: Total Revenue | C13: =C7+C9+C11 -> 51084.5 | D13: =D7+D9+D11 -> 56771.1 | E13: =E7+E9+E11 -> 62369.166 | F13: =F7+F9+F11 -> 67419.839 | G13: =G7+G9+G11 -> 71658.021 | H13: =H7+H9+H11 -> 74007.216
B14: Revenue growth YoY % | C14: =C13/Historico!G6-1 -> 0.13061328 | D14: =D13/C13-1 -> 0.11131752 | E14: =E13/D13-1 -> 0.098607672 | F14: =F13/E13-1 -> 0.080980281 | G14: =G13/F13-1 -> 0.062862546 | H14: =H13/G13-1 -> 0.032783413
L15: Tabla B — Precio (Gordon DCF) vs WACC × Op margin terminal
B16: B. OPERATING INCOME POR SEGMENTO
B17: S1 Suscripcion core — operating income | C17: =C7*Hipotesis!C33 -> 15826.8 | D17: =D7*Hipotesis!D33 -> 17610.912 | E17: =E7*Hipotesis!E33 -> 19397.902 | F17: =F7*Hipotesis!F33 -> 20855.515 | G17: =G7*Hipotesis!G33 -> 22206.718 | H17: =H7*Hipotesis!H33 -> 22872.919 | L17: WACC ↓ \ margin → | M17: 0.4 | N17: 0.43 | O17: 0.46 | P17: 0.49 | Q17: 0.52
B18: S1 Suscripcion core — op margin % | C18: =C17/C7 -> 0.33 | D18: =D17/D7 -> 0.34 | E18: =E17/E7 -> 0.35 | F18: =F17/F7 -> 0.355 | G18: =G17/G7 -> 0.36 | H18: =H17/H7 -> 0.36 | L18: 0.075 | M18: =(C41+((G13*M$17*(1-Hipotesis!$C$13)+G28+G30+G32)*(1+Hipotesis!$C$47)/($L$18-Hipotesis!$C$47))/(1+$L$18)^5+Hipotesis!$C$15+Hipotesis!$C$16-Hipotesis!$C$14)/Hipotesis!$C$8 -> 99.203977 | N18: =(C41+((G13*N$17*(1-Hipotesis!$C$13)+G28+G30+G32)*(1+Hipotesis!$C$47)/($L$18-Hipotesis!$C$47))/(1+$L$18)^5+Hipotesis!$C$15+Hipotesis!$C$16-Hipotesis!$C$14)/Hipotesis!$C$8 -> 105.71258 | O18: =(C41+((G13*O$17*(1-Hipotesis!$C$13)+G28+G30+G32)*(1+Hipotesis!$C$47)/($L$18-Hipotesis!$C$47))/(1+$L$18)^5+Hipotesis!$C$15+Hipotesis!$C$16-Hipotesis!$C$14)/Hipotesis!$C$8 -> 112.22118 | P18: =(C41+((G13*P$17*(1-Hipotesis!$C$13)+G28+G30+G32)*(1+Hipotesis!$C$47)/($L$18-Hipotesis!$C$47))/(1+$L$18)^5+Hipotesis!$C$15+Hipotesis!$C$16-Hipotesis!$C$14)/Hipotesis!$C$8 -> 118.72978 | Q18: =(C41+((G13*Q$17*(1-Hipotesis!$C$13)+G28+G30+G32)*(1+Hipotesis!$C$47)/($L$18-Hipotesis!$C$47))/(1+$L$18)^5+Hipotesis!$C$15+Hipotesis!$C$16-Hipotesis!$C$14)/Hipotesis!$C$8 -> 125.23838
B19: S2 Publicidad (motor crecimiento) operating income | C19: =C9*Hipotesis!C34 -> 150 | D19: =D9*Hipotesis!D34 -> 576 | E19: =E9*Hipotesis!E34 -> 1209.6 | F19: =F9*Hipotesis!F34 -> 1932 | G19: =G9*Hipotesis!G34 -> 2704.8 | H19: =H9*Hipotesis!H34 -> 3042.9 | L19: 0.085 | M19: =(C41+((G13*M$17*(1-Hipotesis!$C$13)+G28+G30+G32)*(1+Hipotesis!$C$47)/($L$19-Hipotesis!$C$47))/(1+$L$19)^5+Hipotesis!$C$15+Hipotesis!$C$16-Hipotesis!$C$14)/Hipotesis!$C$8 -> 80.569364 | N19: =(C41+((G13*N$17*(1-Hipotesis!$C$13)+G28+G30+G32)*(1+Hipotesis!$C$47)/($L$19-Hipotesis!$C$47))/(1+$L$19)^5+Hipotesis!$C$15+Hipotesis!$C$16-Hipotesis!$C$14)/Hipotesis!$C$8 -> 85.653663 | O19: =(C41+((G13*O$17*(1-Hipotesis!$C$13)+G28+G30+G32)*(1+Hipotesis!$C$47)/($L$19-Hipotesis!$C$47))/(1+$L$19)^5+Hipotesis!$C$15+Hipotesis!$C$16-Hipotesis!$C$14)/Hipotesis!$C$8 -> 90.737962 | P19: =(C41+((G13*P$17*(1-Hipotesis!$C$13)+G28+G30+G32)*(1+Hipotesis!$C$47)/($L$19-Hipotesis!$C$47))/(1+$L$19)^5+Hipotesis!$C$15+Hipotesis!$C$16-Hipotesis!$C$14)/Hipotesis!$C$8 -> 95.82226 | Q19: =(C41+((G13*Q$17*(1-Hipotesis!$C$13)+G28+G30+G32)*(1+Hipotesis!$C$47)/($L$19-Hipotesis!$C$47))/(1+$L$19)^5+Hipotesis!$C$15+Hipotesis!$C$16-Hipotesis!$C$14)/Hipotesis!$C$8 -> 100.90656
B20: S2 Publicidad — op margin % | C20: =C19/C9 -> 0.05 | D20: =D19/D9 -> 0.12 | E20: =E19/E9 -> 0.18 | F20: =F19/F9 -> 0.23 | G20: =G19/G9 -> 0.28 | H20: =H19/H9 -> 0.3 | L20: 0.0912 | M20: =(C41+((G13*M$17*(1-Hipotesis!$C$13)+G28+G30+G32)*(1+Hipotesis!$C$47)/($L$20-Hipotesis!$C$47))/(1+$L$20)^5+Hipotesis!$C$15+Hipotesis!$C$16-Hipotesis!$C$14)/Hipotesis!$C$8 -> 72.151328 | N20: =(C41+((G13*N$17*(1-Hipotesis!$C$13)+G28+G30+G32)*(1+Hipotesis!$C$47)/($L$20-Hipotesis!$C$47))/(1+$L$20)^5+Hipotesis!$C$15+Hipotesis!$C$16-Hipotesis!$C$14)/Hipotesis!$C$8 -> 76.59221 | O20: =(C41+((G13*O$17*(1-Hipotesis!$C$13)+G28+G30+G32)*(1+Hipotesis!$C$47)/($L$20-Hipotesis!$C$47))/(1+$L$20)^5+Hipotesis!$C$15+Hipotesis!$C$16-Hipotesis!$C$14)/Hipotesis!$C$8 -> 81.033092 | P20: =(C41+((G13*P$17*(1-Hipotesis!$C$13)+G28+G30+G32)*(1+Hipotesis!$C$47)/($L$20-Hipotesis!$C$47))/(1+$L$20)^5+Hipotesis!$C$15+Hipotesis!$C$16-Hipotesis!$C$14)/Hipotesis!$C$8 -> 85.473974 | Q20: =(C41+((G13*Q$17*(1-Hipotesis!$C$13)+G28+G30+G32)*(1+Hipotesis!$C$47)/($L$20-Hipotesis!$C$47))/(1+$L$20)^5+Hipotesis!$C$15+Hipotesis!$C$16-Hipotesis!$C$14)/Hipotesis!$C$8 -> 89.914856
B21: S3 Otros — operating income | C21: =C11*Hipotesis!C35 -> 6.225 | D21: =D11*Hipotesis!D35 -> 17.43 | E21: =E11*Hipotesis!E35 -> 27.1908 | F21: =F11*Hipotesis!F35 -> 40.7862 | G21: =G11*Hipotesis!G35 -> 56.284956 | H21: =H11*Hipotesis!H35 -> 65.665782 | L21: 0.1 | M21: =(C41+((G13*M$17*(1-Hipotesis!$C$13)+G28+G30+G32)*(1+Hipotesis!$C$47)/($L$21-Hipotesis!$C$47))/(1+$L$21)^5+Hipotesis!$C$15+Hipotesis!$C$16-Hipotesis!$C$14)/Hipotesis!$C$8 -> 62.847492 | N21: =(C41+((G13*N$17*(1-Hipotesis!$C$13)+G28+G30+G32)*(1+Hipotesis!$C$47)/($L$21-Hipotesis!$C$47))/(1+$L$21)^5+Hipotesis!$C$15+Hipotesis!$C$16-Hipotesis!$C$14)/Hipotesis!$C$8 -> 66.577253 | O21: =(C41+((G13*O$17*(1-Hipotesis!$C$13)+G28+G30+G32)*(1+Hipotesis!$C$47)/($L$21-Hipotesis!$C$47))/(1+$L$21)^5+Hipotesis!$C$15+Hipotesis!$C$16-Hipotesis!$C$14)/Hipotesis!$C$8 -> 70.307014 | P21: =(C41+((G13*P$17*(1-Hipotesis!$C$13)+G28+G30+G32)*(1+Hipotesis!$C$47)/($L$21-Hipotesis!$C$47))/(1+$L$21)^5+Hipotesis!$C$15+Hipotesis!$C$16-Hipotesis!$C$14)/Hipotesis!$C$8 -> 74.036775 | Q21: =(C41+((G13*Q$17*(1-Hipotesis!$C$13)+G28+G30+G32)*(1+Hipotesis!$C$47)/($L$21-Hipotesis!$C$47))/(1+$L$21)^5+Hipotesis!$C$15+Hipotesis!$C$16-Hipotesis!$C$14)/Hipotesis!$C$8 -> 77.766535
B22: S3 Otros — op margin % | C22: =C21/C11 -> 0.05 | D22: =D21/D11 -> 0.1 | E22: =E21/E11 -> 0.12 | F22: =F21/F11 -> 0.15 | G22: =G21/G11 -> 0.18 | H22: =H21/H11 -> 0.2 | L22: 0.11 | M22: =(C41+((G13*M$17*(1-Hipotesis!$C$13)+G28+G30+G32)*(1+Hipotesis!$C$47)/($L$22-Hipotesis!$C$47))/(1+$L$22)^5+Hipotesis!$C$15+Hipotesis!$C$16-Hipotesis!$C$14)/Hipotesis!$C$8 -> 54.858791 | N22: =(C41+((G13*N$17*(1-Hipotesis!$C$13)+G28+G30+G32)*(1+Hipotesis!$C$47)/($L$22-Hipotesis!$C$47))/(1+$L$22)^5+Hipotesis!$C$15+Hipotesis!$C$16-Hipotesis!$C$14)/Hipotesis!$C$8 -> 57.97795 | O22: =(C41+((G13*O$17*(1-Hipotesis!$C$13)+G28+G30+G32)*(1+Hipotesis!$C$47)/($L$22-Hipotesis!$C$47))/(1+$L$22)^5+Hipotesis!$C$15+Hipotesis!$C$16-Hipotesis!$C$14)/Hipotesis!$C$8 -> 61.097109 | P22: =(C41+((G13*P$17*(1-Hipotesis!$C$13)+G28+G30+G32)*(1+Hipotesis!$C$47)/($L$22-Hipotesis!$C$47))/(1+$L$22)^5+Hipotesis!$C$15+Hipotesis!$C$16-Hipotesis!$C$14)/Hipotesis!$C$8 -> 64.216269 | Q22: =(C41+((G13*Q$17*(1-Hipotesis!$C$13)+G28+G30+G32)*(1+Hipotesis!$C$47)/($L$22-Hipotesis!$C$47))/(1+$L$22)^5+Hipotesis!$C$15+Hipotesis!$C$16-Hipotesis!$C$14)/Hipotesis!$C$8 -> 67.335428
B23: Total Operating Income (EBIT) | C23: =C17+C19+C21 -> 15983.025 | D23: =D17+D19+D21 -> 18204.342 | E23: =E17+E19+E21 -> 20634.692 | F23: =F17+F19+F21 -> 22828.302 | G23: =G17+G19+G21 -> 24967.803 | H23: =H17+H19+H21 -> 25981.485
B24: Operating margin % | C24: =C23/C13 -> 0.31287426 | D24: =D23/D13 -> 0.32066213 | E24: =E23/E13 -> 0.33084766 | F24: =F23/F13 -> 0.33859917 | G24: =G23/G13 -> 0.34842998 | H24: =H23/H13 -> 0.35106692 | L24: Tabla C — Precio (Gordon DCF) vs Capex/Rev terminal × g_terminal
B26: C. PUENTE DE EBIT A FREE CASH FLOW (FCFF) | L26: Capex/Rev ↓ \ g → | M26: 0.02 | N26: 0.025 | O26: 0.03 | P26: 0.035 | Q26: 0.04
B27: NOPAT = EBIT × (1 − tax rate) | C27: =C23*(1-Hipotesis!$C$13) -> 12786.42 | D27: =D23*(1-Hipotesis!$C$13) -> 14563.474 | E27: =E23*(1-Hipotesis!$C$13) -> 16507.754 | F27: =F23*(1-Hipotesis!$C$13) -> 18262.641 | G27: =G23*(1-Hipotesis!$C$13) -> 19974.242 | H27: =H23*(1-Hipotesis!$C$13) -> 20785.188 | L27: 0.1 | M27: =(C41+((G27+G28+(-G13*$L$27)+G32)*(1+M$26)/(Hipotesis!$C$25-M$26))/(1+Hipotesis!$C$25)^5+Hipotesis!$C$15+Hipotesis!$C$16-Hipotesis!$C$14)/Hipotesis!$C$8 -> 40.873063 | N27: =(C41+((G27+G28+(-G13*$L$27)+G32)*(1+N$26)/(Hipotesis!$C$25-N$26))/(1+Hipotesis!$C$25)^5+Hipotesis!$C$15+Hipotesis!$C$16-Hipotesis!$C$14)/Hipotesis!$C$8 -> 42.895278 | O27: =(C41+((G27+G28+(-G13*$L$27)+G32)*(1+O$26)/(Hipotesis!$C$25-O$26))/(1+Hipotesis!$C$25)^5+Hipotesis!$C$15+Hipotesis!$C$16-Hipotesis!$C$14)/Hipotesis!$C$8 -> 45.222589 | P27: =(C41+((G27+G28+(-G13*$L$27)+G32)*(1+P$26)/(Hipotesis!$C$25-P$26))/(1+Hipotesis!$C$25)^5+Hipotesis!$C$15+Hipotesis!$C$16-Hipotesis!$C$14)/Hipotesis!$C$8 -> 47.929674 | Q27: =(C41+((G27+G28+(-G13*$L$27)+G32)*(1+Q$26)/(Hipotesis!$C$25-Q$26))/(1+Hipotesis!$C$25)^5+Hipotesis!$C$15+Hipotesis!$C$16-Hipotesis!$C$14)/Hipotesis!$C$8 -> 51.117749
B28: (+) D&A | C28: =C13*Hipotesis!C40 -> 408.676 | D28: =D13*Hipotesis!D40 -> 454.1688 | E28: =E13*Hipotesis!E40 -> 498.95333 | F28: =F13*Hipotesis!F40 -> 539.35871 | G28: =G13*Hipotesis!G40 -> 573.26417 | H28: =H13*Hipotesis!H40 -> 592.05773 | L28: 0.125 | M28: =(C41+((G27+G28+(-G13*$L$28)+G32)*(1+M$26)/(Hipotesis!$C$25-M$26))/(1+Hipotesis!$C$25)^5+Hipotesis!$C$15+Hipotesis!$C$16-Hipotesis!$C$14)/Hipotesis!$C$8 -> 37.282148 | N28: =(C41+((G27+G28+(-G13*$L$28)+G32)*(1+N$26)/(Hipotesis!$C$25-N$26))/(1+Hipotesis!$C$25)^5+Hipotesis!$C$15+Hipotesis!$C$16-Hipotesis!$C$14)/Hipotesis!$C$8 -> 39.033643 | O28: =(C41+((G27+G28+(-G13*$L$28)+G32)*(1+O$26)/(Hipotesis!$C$25-O$26))/(1+Hipotesis!$C$25)^5+Hipotesis!$C$15+Hipotesis!$C$16-Hipotesis!$C$14)/Hipotesis!$C$8 -> 41.049389 | P28: =(C41+((G27+G28+(-G13*$L$28)+G32)*(1+P$26)/(Hipotesis!$C$25-P$26))/(1+Hipotesis!$C$25)^5+Hipotesis!$C$15+Hipotesis!$C$16-Hipotesis!$C$14)/Hipotesis!$C$8 -> 43.394068 | Q28: =(C41+((G27+G28+(-G13*$L$28)+G32)*(1+Q$26)/(Hipotesis!$C$25-Q$26))/(1+Hipotesis!$C$25)^5+Hipotesis!$C$15+Hipotesis!$C$16-Hipotesis!$C$14)/Hipotesis!$C$8 -> 46.155346
B29: D&A / Revenue % | C29: =C28/C13 -> 0.008 | D29: =D28/D13 -> 0.008 | E29: =E28/E13 -> 0.008 | F29: =F28/F13 -> 0.008 | G29: =G28/G13 -> 0.008 | H29: =H28/H13 -> 0.008 | L29: 0.15 | M29: =(C41+((G27+G28+(-G13*$L$29)+G32)*(1+M$26)/(Hipotesis!$C$25-M$26))/(1+Hipotesis!$C$25)^5+Hipotesis!$C$15+Hipotesis!$C$16-Hipotesis!$C$14)/Hipotesis!$C$8 -> 33.691232 | N29: =(C41+((G27+G28+(-G13*$L$29)+G32)*(1+N$26)/(Hipotesis!$C$25-N$26))/(1+Hipotesis!$C$25)^5+Hipotesis!$C$15+Hipotesis!$C$16-Hipotesis!$C$14)/Hipotesis!$C$8 -> 35.172007 | O29: =(C41+((G27+G28+(-G13*$L$29)+G32)*(1+O$26)/(Hipotesis!$C$25-O$26))/(1+Hipotesis!$C$25)^5+Hipotesis!$C$15+Hipotesis!$C$16-Hipotesis!$C$14)/Hipotesis!$C$8 -> 36.876189 | P29: =(C41+((G27+G28+(-G13*$L$29)+G32)*(1+P$26)/(Hipotesis!$C$25-P$26))/(1+Hipotesis!$C$25)^5+Hipotesis!$C$15+Hipotesis!$C$16-Hipotesis!$C$14)/Hipotesis!$C$8 -> 38.858462 | Q29: =(C41+((G27+G28+(-G13*$L$29)+G32)*(1+Q$26)/(Hipotesis!$C$25-Q$26))/(1+Hipotesis!$C$25)^5+Hipotesis!$C$15+Hipotesis!$C$16-Hipotesis!$C$14)/Hipotesis!$C$8 -> 41.192942
B30: (−) Capex | C30: =-C13*Hipotesis!C39 -> -766.2675 | D30: =-D13*Hipotesis!D39 -> -851.5665 | E30: =-E13*Hipotesis!E39 -> -935.53749 | F30: =-F13*Hipotesis!F39 -> -943.87774 | G30: =-G13*Hipotesis!G39 -> -1003.2123 | H30: =-H13*Hipotesis!H39 -> -962.09381 | L30: 0.175 | M30: =(C41+((G27+G28+(-G13*$L$30)+G32)*(1+M$26)/(Hipotesis!$C$25-M$26))/(1+Hipotesis!$C$25)^5+Hipotesis!$C$15+Hipotesis!$C$16-Hipotesis!$C$14)/Hipotesis!$C$8 -> 30.100317 | N30: =(C41+((G27+G28+(-G13*$L$30)+G32)*(1+N$26)/(Hipotesis!$C$25-N$26))/(1+Hipotesis!$C$25)^5+Hipotesis!$C$15+Hipotesis!$C$16-Hipotesis!$C$14)/Hipotesis!$C$8 -> 31.310371 | O30: =(C41+((G27+G28+(-G13*$L$30)+G32)*(1+O$26)/(Hipotesis!$C$25-O$26))/(1+Hipotesis!$C$25)^5+Hipotesis!$C$15+Hipotesis!$C$16-Hipotesis!$C$14)/Hipotesis!$C$8 -> 32.702989 | P30: =(C41+((G27+G28+(-G13*$L$30)+G32)*(1+P$26)/(Hipotesis!$C$25-P$26))/(1+Hipotesis!$C$25)^5+Hipotesis!$C$15+Hipotesis!$C$16-Hipotesis!$C$14)/Hipotesis!$C$8 -> 34.322856 | Q30: =(C41+((G27+G28+(-G13*$L$30)+G32)*(1+Q$26)/(Hipotesis!$C$25-Q$26))/(1+Hipotesis!$C$25)^5+Hipotesis!$C$15+Hipotesis!$C$16-Hipotesis!$C$14)/Hipotesis!$C$8 -> 36.230539
B31: Capex / Revenue % | C31: =-C30/C13 -> 0.015 | D31: =-D30/D13 -> 0.015 | E31: =-E30/E13 -> 0.015 | F31: =-F30/F13 -> 0.014 | G31: =-G30/G13 -> 0.014 | H31: =-H30/H13 -> 0.013 | L31: 0.2 | M31: =(C41+((G27+G28+(-G13*$L$31)+G32)*(1+M$26)/(Hipotesis!$C$25-M$26))/(1+Hipotesis!$C$25)^5+Hipotesis!$C$15+Hipotesis!$C$16-Hipotesis!$C$14)/Hipotesis!$C$8 -> 26.509402 | N31: =(C41+((G27+G28+(-G13*$L$31)+G32)*(1+N$26)/(Hipotesis!$C$25-N$26))/(1+Hipotesis!$C$25)^5+Hipotesis!$C$15+Hipotesis!$C$16-Hipotesis!$C$14)/Hipotesis!$C$8 -> 27.448736 | O31: =(C41+((G27+G28+(-G13*$L$31)+G32)*(1+O$26)/(Hipotesis!$C$25-O$26))/(1+Hipotesis!$C$25)^5+Hipotesis!$C$15+Hipotesis!$C$16-Hipotesis!$C$14)/Hipotesis!$C$8 -> 28.529789 | P31: =(C41+((G27+G28+(-G13*$L$31)+G32)*(1+P$26)/(Hipotesis!$C$25-P$26))/(1+Hipotesis!$C$25)^5+Hipotesis!$C$15+Hipotesis!$C$16-Hipotesis!$C$14)/Hipotesis!$C$8 -> 29.78725 | Q31: =(C41+((G27+G28+(-G13*$L$31)+G32)*(1+Q$26)/(Hipotesis!$C$25-Q$26))/(1+Hipotesis!$C$25)^5+Hipotesis!$C$15+Hipotesis!$C$16-Hipotesis!$C$14)/Hipotesis!$C$8 -> 31.268135
B32: (−) ΔWorking Capital | C32: =-C13*Hipotesis!C42 -> 255.4225 | D32: =-D13*Hipotesis!D42 -> 283.8555 | E32: =-E13*Hipotesis!E42 -> 311.84583 | F32: =-F13*Hipotesis!F42 -> 0 | G32: =-G13*Hipotesis!G42 -> 0 | H32: =-H13*Hipotesis!H42 -> 0
B33: Free Cash Flow to Firm (FCFF) | C33: =C27+C28+C30+C32 -> 12684.251 | D33: =D27+D28+D30+D32 -> 14449.931 | E33: =E27+E28+E30+E32 -> 16383.016 | F33: =F27+F28+F30+F32 -> 17858.122 | G33: =G27+G28+G30+G32 -> 19544.294 | H33: =H27+H28+H30+H32 -> 20415.152 | L33: Tabla D — Precio (Exit EV/EBITDA) vs WACC × Exit EV/EBITDA
B34: FCFF / Revenue % | C34: =C33/C13 -> 0.24829941 | D34: =D33/D13 -> 0.25452971 | E34: =E33/E13 -> 0.26267813 | F34: =F33/F13 -> 0.26487934 | G34: =G33/G13 -> 0.27274398 | H34: =H33/H13 -> 0.27585353
B35: FCFF / NOPAT % (conversion) | C35: =C33/C27 -> 0.99200957 | D35: =D33/D27 -> 0.99220363 | E35: =E33/E27 -> 0.99244365 | F35: =F33/F27 -> 0.97784992 | G35: =G33/G27 -> 0.97847487 | H35: =H33/H27 -> 0.98219713 | L35: WACC ↓ \ EV/EBITDA → | M35: 16 | N35: 18 | O35: 20 | P35: 22 | Q35: 24
L36: 0.075 | M36: =((C33/(1+$L$36)^0.5 + D33/(1+$L$36)^1.5 + E33/(1+$L$36)^2.5 + F33/(1+$L$36)^3.5 + G33/(1+$L$36)^4.5)+(M$35*(G23+G28))/(1+$L$36)^5+Hipotesis!$C$15+Hipotesis!$C$16-Hipotesis!$C$14)/Hipotesis!$C$8 -> 82.392395 | N36: =((C33/(1+$L$36)^0.5 + D33/(1+$L$36)^1.5 + E33/(1+$L$36)^2.5 + F33/(1+$L$36)^3.5 + G33/(1+$L$36)^4.5)+(N$35*(G23+G28))/(1+$L$36)^5+Hipotesis!$C$15+Hipotesis!$C$16-Hipotesis!$C$14)/Hipotesis!$C$8 -> 90.838488 | O36: =((C33/(1+$L$36)^0.5 + D33/(1+$L$36)^1.5 + E33/(1+$L$36)^2.5 + F33/(1+$L$36)^3.5 + G33/(1+$L$36)^4.5)+(O$35*(G23+G28))/(1+$L$36)^5+Hipotesis!$C$15+Hipotesis!$C$16-Hipotesis!$C$14)/Hipotesis!$C$8 -> 99.284581 | P36: =((C33/(1+$L$36)^0.5 + D33/(1+$L$36)^1.5 + E33/(1+$L$36)^2.5 + F33/(1+$L$36)^3.5 + G33/(1+$L$36)^4.5)+(P$35*(G23+G28))/(1+$L$36)^5+Hipotesis!$C$15+Hipotesis!$C$16-Hipotesis!$C$14)/Hipotesis!$C$8 -> 107.73067 | Q36: =((C33/(1+$L$36)^0.5 + D33/(1+$L$36)^1.5 + E33/(1+$L$36)^2.5 + F33/(1+$L$36)^3.5 + G33/(1+$L$36)^4.5)+(Q$35*(G23+G28))/(1+$L$36)^5+Hipotesis!$C$15+Hipotesis!$C$16-Hipotesis!$C$14)/Hipotesis!$C$8 -> 116.17677
B37: D. DCF DISCOUNTING & VALUE BRIDGE | L37: 0.085 | M37: =((C33/(1+$L$37)^0.5 + D33/(1+$L$37)^1.5 + E33/(1+$L$37)^2.5 + F33/(1+$L$37)^3.5 + G33/(1+$L$37)^4.5)+(M$35*(G23+G28))/(1+$L$37)^5+Hipotesis!$C$15+Hipotesis!$C$16-Hipotesis!$C$14)/Hipotesis!$C$8 -> 78.963687 | N37: =((C33/(1+$L$37)^0.5 + D33/(1+$L$37)^1.5 + E33/(1+$L$37)^2.5 + F33/(1+$L$37)^3.5 + G33/(1+$L$37)^4.5)+(N$35*(G23+G28))/(1+$L$37)^5+Hipotesis!$C$15+Hipotesis!$C$16-Hipotesis!$C$14)/Hipotesis!$C$8 -> 87.027668 | O37: =((C33/(1+$L$37)^0.5 + D33/(1+$L$37)^1.5 + E33/(1+$L$37)^2.5 + F33/(1+$L$37)^3.5 + G33/(1+$L$37)^4.5)+(O$35*(G23+G28))/(1+$L$37)^5+Hipotesis!$C$15+Hipotesis!$C$16-Hipotesis!$C$14)/Hipotesis!$C$8 -> 95.091649 | P37: =((C33/(1+$L$37)^0.5 + D33/(1+$L$37)^1.5 + E33/(1+$L$37)^2.5 + F33/(1+$L$37)^3.5 + G33/(1+$L$37)^4.5)+(P$35*(G23+G28))/(1+$L$37)^5+Hipotesis!$C$15+Hipotesis!$C$16-Hipotesis!$C$14)/Hipotesis!$C$8 -> 103.15563 | Q37: =((C33/(1+$L$37)^0.5 + D33/(1+$L$37)^1.5 + E33/(1+$L$37)^2.5 + F33/(1+$L$37)^3.5 + G33/(1+$L$37)^4.5)+(Q$35*(G23+G28))/(1+$L$37)^5+Hipotesis!$C$15+Hipotesis!$C$16-Hipotesis!$C$14)/Hipotesis!$C$8 -> 111.21961
B38: Período (años desde valoración) | C38: 0.5 | D38: 1.5 | E38: 2.5 | F38: 3.5 | G38: 4.5 | H38: TV at end FY30 | L38: 0.0912 | M38: =((C33/(1+$L$38)^0.5 + D33/(1+$L$38)^1.5 + E33/(1+$L$38)^2.5 + F33/(1+$L$38)^3.5 + G33/(1+$L$38)^4.5)+(M$35*(G23+G28))/(1+$L$38)^5+Hipotesis!$C$15+Hipotesis!$C$16-Hipotesis!$C$14)/Hipotesis!$C$8 -> 76.928495 | N38: =((C33/(1+$L$38)^0.5 + D33/(1+$L$38)^1.5 + E33/(1+$L$38)^2.5 + F33/(1+$L$38)^3.5 + G33/(1+$L$38)^4.5)+(N$35*(G23+G28))/(1+$L$38)^5+Hipotesis!$C$15+Hipotesis!$C$16-Hipotesis!$C$14)/Hipotesis!$C$8 -> 84.765974 | O38: =((C33/(1+$L$38)^0.5 + D33/(1+$L$38)^1.5 + E33/(1+$L$38)^2.5 + F33/(1+$L$38)^3.5 + G33/(1+$L$38)^4.5)+(O$35*(G23+G28))/(1+$L$38)^5+Hipotesis!$C$15+Hipotesis!$C$16-Hipotesis!$C$14)/Hipotesis!$C$8 -> 92.603454 | P38: =((C33/(1+$L$38)^0.5 + D33/(1+$L$38)^1.5 + E33/(1+$L$38)^2.5 + F33/(1+$L$38)^3.5 + G33/(1+$L$38)^4.5)+(P$35*(G23+G28))/(1+$L$38)^5+Hipotesis!$C$15+Hipotesis!$C$16-Hipotesis!$C$14)/Hipotesis!$C$8 -> 100.44093 | Q38: =((C33/(1+$L$38)^0.5 + D33/(1+$L$38)^1.5 + E33/(1+$L$38)^2.5 + F33/(1+$L$38)^3.5 + G33/(1+$L$38)^4.5)+(Q$35*(G23+G28))/(1+$L$38)^5+Hipotesis!$C$15+Hipotesis!$C$16-Hipotesis!$C$14)/Hipotesis!$C$8 -> 108.27841
B39: Discount factor (mid-year) | C39: =1/(1+Hipotesis!$C$25)^C38 -> 0.95507829 | D39: =1/(1+Hipotesis!$C$25)^D38 -> 0.87119811 | E39: =1/(1+Hipotesis!$C$25)^E38 -> 0.79468474 | F39: =1/(1+Hipotesis!$C$25)^F38 -> 0.72489119 | G39: =1/(1+Hipotesis!$C$25)^G38 -> 0.66122729 | H39: — | L39: 0.1 | M39: =((C33/(1+$L$39)^0.5 + D33/(1+$L$39)^1.5 + E33/(1+$L$39)^2.5 + F33/(1+$L$39)^3.5 + G33/(1+$L$39)^4.5)+(M$35*(G23+G28))/(1+$L$39)^5+Hipotesis!$C$15+Hipotesis!$C$16-Hipotesis!$C$14)/Hipotesis!$C$8 -> 74.152787 | N39: =((C33/(1+$L$39)^0.5 + D33/(1+$L$39)^1.5 + E33/(1+$L$39)^2.5 + F33/(1+$L$39)^3.5 + G33/(1+$L$39)^4.5)+(N$35*(G23+G28))/(1+$L$39)^5+Hipotesis!$C$15+Hipotesis!$C$16-Hipotesis!$C$14)/Hipotesis!$C$8 -> 81.681743 | O39: =((C33/(1+$L$39)^0.5 + D33/(1+$L$39)^1.5 + E33/(1+$L$39)^2.5 + F33/(1+$L$39)^3.5 + G33/(1+$L$39)^4.5)+(O$35*(G23+G28))/(1+$L$39)^5+Hipotesis!$C$15+Hipotesis!$C$16-Hipotesis!$C$14)/Hipotesis!$C$8 -> 89.2107 | P39: =((C33/(1+$L$39)^0.5 + D33/(1+$L$39)^1.5 + E33/(1+$L$39)^2.5 + F33/(1+$L$39)^3.5 + G33/(1+$L$39)^4.5)+(P$35*(G23+G28))/(1+$L$39)^5+Hipotesis!$C$15+Hipotesis!$C$16-Hipotesis!$C$14)/Hipotesis!$C$8 -> 96.739656 | Q39: =((C33/(1+$L$39)^0.5 + D33/(1+$L$39)^1.5 + E33/(1+$L$39)^2.5 + F33/(1+$L$39)^3.5 + G33/(1+$L$39)^4.5)+(Q$35*(G23+G28))/(1+$L$39)^5+Hipotesis!$C$15+Hipotesis!$C$16-Hipotesis!$C$14)/Hipotesis!$C$8 -> 104.26861
B40: PV of FCFF (explicit period) | C40: =C33*C39 -> 12114.453 | D40: =D33*D39 -> 12588.753 | E40: =E33*E39 -> 13019.332 | F40: =F33*F39 -> 12945.195 | G40: =G33*G39 -> 12923.221 | H40: (see TV below) | L40: 0.11 | M40: =((C33/(1+$L$40)^0.5 + D33/(1+$L$40)^1.5 + E33/(1+$L$40)^2.5 + F33/(1+$L$40)^3.5 + G33/(1+$L$40)^4.5)+(M$35*(G23+G28))/(1+$L$40)^5+Hipotesis!$C$15+Hipotesis!$C$16-Hipotesis!$C$14)/Hipotesis!$C$8 -> 71.151257 | N40: =((C33/(1+$L$40)^0.5 + D33/(1+$L$40)^1.5 + E33/(1+$L$40)^2.5 + F33/(1+$L$40)^3.5 + G33/(1+$L$40)^4.5)+(N$35*(G23+G28))/(1+$L$40)^5+Hipotesis!$C$15+Hipotesis!$C$16-Hipotesis!$C$14)/Hipotesis!$C$8 -> 78.347127 | O40: =((C33/(1+$L$40)^0.5 + D33/(1+$L$40)^1.5 + E33/(1+$L$40)^2.5 + F33/(1+$L$40)^3.5 + G33/(1+$L$40)^4.5)+(O$35*(G23+G28))/(1+$L$40)^5+Hipotesis!$C$15+Hipotesis!$C$16-Hipotesis!$C$14)/Hipotesis!$C$8 -> 85.542997 | P40: =((C33/(1+$L$40)^0.5 + D33/(1+$L$40)^1.5 + E33/(1+$L$40)^2.5 + F33/(1+$L$40)^3.5 + G33/(1+$L$40)^4.5)+(P$35*(G23+G28))/(1+$L$40)^5+Hipotesis!$C$15+Hipotesis!$C$16-Hipotesis!$C$14)/Hipotesis!$C$8 -> 92.738867 | Q40: =((C33/(1+$L$40)^0.5 + D33/(1+$L$40)^1.5 + E33/(1+$L$40)^2.5 + F33/(1+$L$40)^3.5 + G33/(1+$L$40)^4.5)+(Q$35*(G23+G28))/(1+$L$40)^5+Hipotesis!$C$15+Hipotesis!$C$16-Hipotesis!$C$14)/Hipotesis!$C$8 -> 99.934736
B41: Σ PV of explicit FCFF | C41: =SUM(C40:G40) -> 63590.954
B43: Cálculos de Valor Terminal (4 métodos)
...

Sheet DuPont_WC
B2: NETFLIX, INC. (NFLX) — DuPont Decomposition + Working Capital Analysis
B3: Periodo FY21-FY25 + Q1 2026. Datos en $mm except ratios. NFLX fiscal year = calendar year.
B5: 1. INPUTS HISTORICOS (Source: NFLX 10-K FY2025 + 10-Q Q1 2026, SEC EDGAR)
C6: FY2021 | D6: FY2022 | E6: FY2023 | F6: FY2024 | G6: FY2025 | H6: Q1 2026
B7: Revenue ($mm) | C7: 29698 | D7: 31616 | E7: 33723 | F7: 39001 | G7: 45183 | H7: 12250 | I7: 10-K Income Statement + 10-Q
B8: Operating Income ($mm) | C8: 6195 | D8: 5633 | E8: 6954 | F8: 10418 | G8: 13327 | H8: 3957
B9: Net Income ($mm) | C9: 5116 | D9: 4492 | E9: 5408 | F9: 8712 | G9: 10981 | H9: 5283
B10: Total Assets ($mm) | C10: 44585 | D10: 48595 | E10: 48732 | F10: 53630 | G10: 55597 | H10: 60000 | I10: Balance Sheet; Q1 2026 estimate (no full BS disclosure in 10-Q yet released)
B11: Stockholders' Equity ($mm) | C11: 15849 | D11: 20777 | E11: 20588 | F11: 24744 | G11: 26615 | H11: 30700
B12: Total Debt (incl. current portion) ($mm) | C12: 14693 | D12: 14353 | E12: 14143 | F12: 13798 | G12: 13464 | H12: 13400
B13: Cash + STI ($mm) | C13: 6028 | D13: 6058 | E13: 7138 | F13: 9584 | G13: 9062 | H13: 12267
B14: Operating Cash Flow ($mm) | C14: 393 | D14: 2026 | E14: 7274 | F14: 7361 | G14: 10149 | H14: 5290 | I14: Cash Flow Statement
B15: Capex ($mm) | C15: 525 | D15: 408 | E15: 349 | F15: 440 | G15: 688 | H15: 196
B16: Free Cash Flow ($mm) | C16: -132 | D16: 1619 | E16: 6925 | F16: 6921 | G16: 9461 | H16: 5094
B17: D&A ($mm) | C17: 208 | D17: 336 | E17: 297 | F17: 320 | G17: 350 | H17: 99
B18: Effective Tax Rate | C18: 0.226 | D18: 0.149 | E18: 0.229 | F18: 0.228 | G18: 0.209 | H18: 0.193 | I18: 10-K Note Income Taxes. FY22 menor por FX y créditos. Promedio FY23-25 ≈ 22%
B20: 2. DUPONT DECOMPOSITION (ROE = Tax Burden × Interest Burden × OpMargin × Asset Turnover × Equity Multiplier)
C21: FY2021 | D21: FY2022 | E21: FY2023 | F21: FY2024 | G21: FY2025 | H21: 9M parcial
B22: Tax Burden = 1 − effective tax rate | C22: =1-C18 -> 0.774 | D22: =1-D18 -> 0.851 | E22: =1-E18 -> 0.771 | F22: =1-F18 -> 0.772 | G22: =1-G18 -> 0.791 | H22: =1-H18 -> 0.807 | I22: Cuanto retiene la empresa del pretax income
B23: Interest Burden = EBT / EBIT (proxy: (NI/(1-T)) / OI) | C23: =(C9/(1-C18))/C8 -> 1.0669603 | D23: =(D9/(1-D18))/D8 -> 0.93706655 | E23: =(E9/(1-E18))/E8 -> 1.0086665 | F23: =(F9/(1-F18))/F8 -> 1.0832189 | G23: =(G9/(1-G18))/G8 -> 1.0416768 | H23: =(H9/(1-H18))/H8 -> 1.6544019 | I23: >1 indica non-op income positivo (intereses, equity inv gains)
B24: Operating Margin = EBIT / Revenue | C24: =C8/C7 -> 0.20859991 | D24: =D8/D7 -> 0.17816928 | E24: =E8/E7 -> 0.20620941 | F24: =F8/F7 -> 0.26712136 | G24: =G8/G7 -> 0.29495607 | H24: =H8/H7 -> 0.32302041 | I24: Core profitability — clave del bull case
B25: Asset Turnover = Revenue / Total Assets | C25: =C7/C10 -> 0.66609846 | D25: =D7/D10 -> 0.65060191 | E25: =E7/E10 -> 0.69200936 | F25: =F7/F10 -> 0.72722357 | G25: =G7/G10 -> 0.81268773 | H25: =H7/H10 -> 0.20416667 | I25: Cuán eficientemente generan revenue. Cae con $200B+ inversión capex
B26: Equity Multiplier = Total Assets / Equity | C26: =C10/C11 -> 2.8131112 | D26: =D10/D11 -> 2.3388843 | E26: =E10/E11 -> 2.3670099 | F26: =F10/F11 -> 2.1673941 | G26: =G10/G11 -> 2.0889348 | H26: =H10/H11 -> 1.9543974 | I26: Leverage — [EMPRESA] está sobrecapitalizada, declining
B28: ROE (DuPont) = product of 5 factors | C28: =C22*C23*C24*C25*C26 -> 0.32279639 | D28: =D22*D23*D24*D25*D26 -> 0.21620061 | E28: =E22*E23*E24*E25*E26 -> 0.26267729 | F28: =F22*F23*F24*F25*F26 -> 0.35208535 | G28: =G22*G23*G24*G25*G26 -> 0.41258689 | H28: =H22*H23*H24*H25*H26 -> 0.17208469 | I28: Cross-check vs NI/avg Equity ▼
B29: ROE cross-check = NI / period-end Equity | C29: =C9/C11 -> 0.32279639 | D29: =D9/D11 -> 0.21620061 | E29: =E9/E11 -> 0.26267729 | F29: =F9/F11 -> 0.35208535 | G29: =G9/G11 -> 0.41258689 | H29: =H9/H11 -> 0.17208469 | I29: 9M parcial anualizado: ×4/3
B31: 3. ROS2 OPERATIVO (NOPAT / Invested Capital) — métrica relevante para valoración DCF
C32: FY2021 | D32: FY2022 | E32: FY2023 | F32: FY2024 | G32: FY2025 | H32: 9M parcial
B33: NOPAT = EBIT × (1 − effective tax rate) | C33: =C8*(1-C18) -> 4794.93 | D33: =D8*(1-D18) -> 4793.683 | E33: =E8*(1-E18) -> 5361.534 | F33: =F8*(1-F18) -> 8042.696 | G33: =G8*(1-G18) -> 10541.657 | H33: =H8*(1-H18) -> 3193.299 | I33: Excluye non-op income (más conservador que NI)
B34: Invested Capital = Equity + Debt − Excess Cash/STI | C34: =C11+C12-C13 -> 24514 | D34: =D11+D12-D13 -> 29072 | E34: =E11+E12-E13 -> 27593 | F34: =F11+F12-F13 -> 28958 | G34: =G11+G12-G13 -> 31017 | H34: =H11+H12-H13 -> 31833 | I34: Capital efectivamente desplegado en operaciones
B35: ROS2 operativo = NOPAT / S2 | C35: =C33/C34 -> 0.19559966 | D35: =D33/D34 -> 0.16489003 | E35: =E33/E34 -> 0.19430776 | F35: =F33/F34 -> 0.27773658 | G35: =G33/G34 -> 0.33986707 | H35: =H33/H34 -> 0.10031411 | I35: Si baja por capex inversión, valor terminal afectado
B37: ROS2 − WACC spread (WACC=9.12% from Hipotesis!$C$25) | C37: =C35-Hipotesis!$C$25 -> 0.099318245 | D37: =D35-Hipotesis!$C$25 -> 0.068608619 | E37: =E35-Hipotesis!$C$25 -> 0.098026347 | F37: =F35-Hipotesis!$C$25 -> 0.18145517 | G37: =G35-Hipotesis!$C$25 -> 0.24358566 | H37: =H35-Hipotesis!$C$25 -> 0.0040326956 | I37: Spread positivo = creación de valor ([EMPRESA] crónicamente >+20pp)
B39: 4. WORKING CAPITAL DYNAMICS — DSO, DPO, CCC + Backlog visibility
C40: FY2021 | D40: FY2022 | E40: FY2023 | F40: FY2024 | G40: FY2025 | H40: 9M parcial
B41: Accounts Receivable (net, $mm) | C41: 0 | D41: 0 | E41: 0 | F41: 0 | G41: 0 | H41: 0 | I41: NFLX subscription model: cobros prepaid. AR tradicional mínimo
B42: Inventory ($mm) | C42: 0 | D42: 0 | E42: 0 | F42: 0 | G42: 0 | H42: 0 | I42: NFLX digital streaming: inventory mínimo
B43: Accounts Payable ($mm) | C43: 837 | D43: 871 | E43: 747 | F43: 825 | G43: 850 | H43: 850 | I43: AP modesto (NFLX paga rápido a content suppliers)
B44: Unearned Revenue (current, $mm) | C44: 1209 | D44: 1503 | E44: 1442 | F44: 1564 | G44: 1530 | H44: 1500 | I44: Deferred revenue: prepayments ~1 mes promedio. Refleja modelo subscription
B46: DSO = (AR / Revenue) × 365 (annualized for 9M) | C46: =C41/C7*365 -> 0 | D46: =D41/D7*365 -> 0 | E46: =E41/E7*365 -> 0 | F46: =F41/F7*365 -> 0 | G46: =G41/G7*365 -> 0 | H46: =H41/(H7*4/3)*365 -> 0 | I46: Estable ~78-85 días. Sin signos de stretch en collections
B47: DPO = (AP / Revenue) × 365 (proxy; ideal usa COGS) | C47: =C43/C7*365 -> 10.287056 | D47: =D43/D7*365 -> 10.05551 | E47: =E43/E7*365 -> 8.0851348 | F47: =F43/F7*365 -> 7.7209559 | G47: =G43/G7*365 -> 6.8665206 | H47: =H43/(H7*4/3)*365 -> 18.994898 | I47: 9M parcial: AP +$15.8B vs Jun-25 por componentes operativos (en realidad oculta capex)
B48: DIO = (Inventory / Revenue) × 365 | C48: =C42/C7*365 -> 0 | D48: =D42/D7*365 -> 0 | E48: =E42/E7*365 -> 0 | F48: =F42/F7*365 -> 0 | G48: =G42/G7*365 -> 0 | H48: =H42/(H7*4/3)*365 -> 0 | I48: [EMPRESA] software-heavy → inventory minimal
...

Sheet Reverse_DCF
B2: NETFLIX, INC. (NFLX) — REVERSE DCF: ¿Qué pricea el mercado a $87?
B3: Dado spot=$87, ¿qué suposiciones tendrían que ser ciertas? Closed-form solutions — no goal seek manual.
B5: INPUTS COMUNES (link a Modelo/Hipotesis)
B6: Spot price ($) | C6: =Hipotesis!$C$6 -> 87.02
B7: Shares diluidas (M) | C7: =Hipotesis!$C$8 -> 4212.8
B8: Cash + STI ($mm) | C8: =Hipotesis!$C$15 -> 9062
B9: Equity & other investments ($mm) | C9: =Hipotesis!$C$16 -> 0
B10: Total Debt ($mm) | C10: =Hipotesis!$C$14 -> 13464
B11: WACC (caso base) | C11: =Hipotesis!$C$25 -> 0.096281412
B12: Terminal g (caso base) | C12: =Hipotesis!$C$47 -> 0.03
B13: Σ PV explicit FCFF FY26-FY30 (Modelo) | C13: =Modelo!$C$41 -> 63590.954
B14: FY30E FCFF (Modelo) | C14: =Modelo!$G$33 -> 19544.294
B15: FY30E EBIT (Modelo) | C15: =Modelo!$G$23 -> 24967.803
B16: FY30E D&A (Modelo) | C16: =Modelo!$G$28 -> 573.26417
B17: FY30E Revenue (Modelo) | C17: =Modelo!$G$13 -> 71658.021
B18: FY30E NOPAT (Modelo) | C18: =Modelo!$G$27 -> 19974.242
B19: Effective tax rate | C19: =Hipotesis!$C$13 -> 0.2
B21: CÁLCULOS INTERMEDIOS (Δ implícita vs caso base)
B22: Equity target = Spot × Shares ($mm) | C22: =C6*C7 -> 366597.86
B23: (+) Debt | C23: =C10 -> 13464
B24: (−) Cash + STI | C24: =-C8 -> -9062
B25: (−) Equity & other investments | C25: =-C9 -> 0
B26: Enterprise Value target ($mm) | C26: =C22+C10-C8-C9 -> 370999.86
B27: (−) Σ PV explicit FCFF | C27: =-C13 -> -63590.954
B28: PV(TV) implícito ($mm) | C28: =C26-C13 -> 307408.9
B29: TV nominal implícito (×(1+WACC)^5) | C29: =C28*(1+C11)^5 -> 486773.24
B31: A. ¿Qué g_terminal implica el spot? (manteniendo WACC, FCFF base, bridge)
B32: Fórmula: g = (TV·WACC − FCFF_30) / (TV + FCFF_30)
B33: g_terminal implícito (Gordon) | C33: =(C29*C11-C14)/(C29+C14) -> 0.053964003 | D33: vs base 3.0%: | E33: =C33-C12 -> 0.023964003 | G33: Si >0 ↑ → mercado más optimista que base. Si <0 → más pesimista.
B35: B. ¿Qué WACC implica el spot? (manteniendo g_terminal=3%, FCFF base, bridge)
B36: Aproximación: como WACC afecta TV y descuento, no hay fórmula cerrada. Tabla de precios implícitos:
B37: WACC → | C37: 0.075 | D37: 0.085 | E37: 0.0912 | F37: 0.095 | G37: 0.105 | H37: 0.115
