Workbook

Sheet Resumen
A1: UBER / CUADRO DE MANDO - RESUMEN EJECUTIVO Y SNAPSHOT
B2: LEYENDA: | C2: AZUL+AMARILLO | D2: Input hardcoded (editable) | E2: AMARILLO FUERTE | F2: Input clave (driver de sensibilidad) | G2: NEGRO | H2: Formula (calculado) | I2: VERDE | J2: Link a otra hoja | K2: VERDE CLARO | L2: Resultado / output
A4: SNAPSHOT - resumen ejecutivo del libro completo
B6: STOCK / MERCADO | D6: VALORACION DCF | F6: OPERATIONS (FY25) | H6: QUALITY / RETURNS
B7: Spot ($) | C7: =Hipotesis!D55 -> 77.11 | D7: DCF mediana | E7: =MEDIAN(Modelo!D128:G128) -> 103.38241 | F7: Revenue 2025 | G7: =Historico!I7 -> 52017 | H7: ROIC operativo'25 | I7: =DuPont_WC!I37 -> 0.14503325
B8: Market Cap ($M) | C8: =Hipotesis!D55*Hipotesis!D46/1000 -> 159724.96 | D8: DCF promedio | E8: =AVERAGE(Modelo!D128:G128) -> 101.50039 | F8: EBIT 2025 | G8: =Historico!I17 -> 5565 | H8: EBIT margin '25 | I8: =Historico!I18 -> 0.10698426
B9: Enterprise Value | C9: =Hipotesis!D55*Hipotesis!D46/1000+Hipotesis!D51-Hipotesis!D49-Hipotesis!D50-Hipotesis!D52-Hipotesis!D53+Hipotesis!D54 -> 156831.96 | D9: Upside vs spot | E9: =MEDIAN(Modelo!D128:G128)/Hipotesis!D55-1 -> 0.34071343 | F9: Adj EBITDA 2025 | G9: =Historico!I26 -> 8730 | H9: FCF margin '25 | I9: =Historico!I63 -> 0.18768864
B10: 52w range ($) | C10: $68.46 - $101.99 | D10: EV/EBITDA NTM | E10: =$C$9/Modelo!F72 -> 16.88 | F10: FCF 2025 | G10: =Historico!I62 -> 9763 | H10: NWC 2025 ($M) | I10: =DuPont_WC!I64 -> -4613
B11: Acciones dil. (k) | C11: =Hipotesis!D46 -> 2071391 | D11: EV/EBIT NTM | E11: =$C$9/Modelo!F62 -> 18.479252 | F11: Q1'26 Revenue | G11: 13203 | H11: Insurance res. '25 | I11: =DuPont_WC!I57 -> 7450
B13: Tesis: | C13: "Scale Efficiency over Monetization Aggression" - depende de Mobility margin, no de take-rate heroics
B14: Critico Q1'26: | C14: Take rate Mobility paso 30.7% -> 25.8% por cambio UK (merchant->agency); ~9pp del cambio es contable
A16: 1. Q1 2026 HIGHLIGHTS (8-K filed May 6, 2026)
B17: Total Gross Bookings | D17: 53720 | E17: +18% YoY cc
B18: Total Revenue | D18: 13203 | E18: +21% YoY cc
B19: GAAP Operating Income | D19: 1923 | E19: +105% YoY
B20: Adj EBITDA | D20: 2481 | E20: +24% YoY
B21: Non-GAAP Operating Income | D21: 1883 | E21: Nueva metrica primaria
B22: Free Cash Flow | D22: 2286 | E22: +44% YoY
B23: Mobility - Gross Bookings | D23: 26394 | E23: +25% YoY cc
B24: Mobility - Revenue | D24: 6798 | E24: +5% YoY (UK accounting -9pp)
B25: Mobility - Segment Op Income | D25: 2029 | E25: +28% YoY
B26: Delivery - Gross Bookings | D26: 25992 | E26: +23% YoY cc
B27: Delivery - Revenue | D27: 5068 | E27: +25% YoY
B28: Delivery - Segment Op Income | D28: 961 | E28: +43% YoY
... B30: Buybacks (capital returned) | D30: 3000 | E30: $20B program total
A33: 2. HISTORIA FINANCIERA (5 anos)
D34: 2021A | E34: 2022A | F34: 2023A | G34: 2024A | H34: 2025A
B35: Revenue ($M) | D35: =Historico!E7 -> 17455 | E35: =Historico!F7 -> 31877 | F35: =Historico!G7 -> 37281 | G35: =Historico!H7 -> 43978 | H35: =Historico!I7 -> 52017
B36: YoY % | D36: =Historico!E8 -> 0.56701679 | E36: =Historico!F8 -> 0.8262389 | F36: =Historico!G8 -> 0.16952662 | G36: =Historico!H8 -> 0.17963574 | H36: =Historico!I8 -> 0.18279594
B37: Adj EBITDA ($M) | D37: =Historico!E26 -> -774 | E37: =Historico!F26 -> 1713 | F37: =Historico!G26 -> 4052 | G37: =Historico!H26 -> 6484 | H37: =Historico!I26 -> 8730
B38: Adj EBITDA margin | D38: =Historico!E27 -> -0.044342595 | E38: =Historico!F27 -> 0.053737805 | F38: =Historico!G27 -> 0.10868807 | G38: =Historico!H27 -> 0.14743736 | H38: =Historico!I27 -> 0.16782975
B39: FCF ($M) | D39: =Historico!E62 -> 238 | E39: =Historico!F62 -> 390 | F39: =Historico!G62 -> 3361 | G39: =Historico!H62 -> 6895 | H39: =Historico!I62 -> 9763
B40: FCF margin | D40: =Historico!E63 -> 0.013635062 | E40: =Historico!F63 -> 0.012234526 | F40: =Historico!G63 -> 0.090153161 | G40: =Historico!H63 -> 0.15678294 | H40: =Historico!I63 -> 0.18768864
B41: Total Assets ($M) | D41: =Historico!E49 -> 38774 | E41: =Historico!F49 -> 32109 | F41: =Historico!G49 -> 38699 | G41: =Historico!H49 -> 51244 | H41: =Historico!I49 -> 61802
B42: Total Equity ($M) | D42: =Historico!E50 -> 14458 | E42: =Historico!F50 -> 7340 | F42: =Historico!G50 -> 11249 | G42: =Historico!H50 -> 21558 | H42: =Historico!I50 -> 27041
B43: LT Debt ($M) | D43: =Historico!E52 -> 9276 | E43: =Historico!F52 -> 9265 | F43: =Historico!G52 -> 9456 | G43: =Historico!H52 -> 10579 | H43: =Historico!I52 -> 10521
B44: Diluted shares (k) | D44: =Historico!E65 -> 1903053 | E44: =Historico!F65 -> 1992188 | F44: =Historico!G65 -> 2068999 | G44: =Historico!H65 -> 2096810 | H44: =Historico!I65 -> 2119689
A47: 3. MULTIPLOS DE NEGOCIACION (current)
B48: EV / Revenue (NTM 2026E) | D48: =$C$9/Modelo!F55 -> 2.7306628
B49: EV / EBITDA (NTM 2026E) | D49: =$C$9/Modelo!F72 -> 16.88
...

Sheet Hipotesis
A1: HIPOTESIS DEL MODELO / Inputs y Drivers
B2: LEYENDA: | C2: AZUL+AMARILLO | D2: Input hardcoded (editable) | E2: AMARILLO FUERTE | F2: Input clave (driver de sensibilidad) | G2: NEGRO | H2: Formula (calculado) | I2: VERDE | J2: Link a otra hoja | K2: VERDE CLARO | L2: Resultado / output
A4: 1. TASA DE DESCUENTO (WACC)
B5: Tasa libre de riesgo (10Y UST yield) | D5: 0.0435
B6: Equity Risk Premium (ERP) | D6: 0.05
B7: Beta apalancado (5Y) | D7: 1.3
B8: Coste del Equity (Ke = Rf + Beta x ERP) | D8: =D5+D7*D6 -> 0.1085
B9: Coste de deuda pre-impuestos (Kd) | D9: 0.055
B10: Tipo impositivo efectivo (Non-GAAP) | D10: 0.22
B11: Kd post-impuestos = Kd x (1-T) | D11: =D9*(1-D10) -> 0.0429
B12: Peso del Equity (E/EV) | D12: 0.94
B13: Peso de Deuda (D/EV) | D13: =1-D12 -> 0.06
B14: WACC | D14: =D8*D12+D11*D13 -> 0.104564
B15: Tasa de crecimiento perpetuo (g) | D15: 0.025
B16: Multiplo EV/EBITDA salida | D16: 16
B17: Multiplo EV/EBIT salida | D17: 18
D19: 2023A | E19: 2024A | F19: 2025A | G19: 2026E | H19: 2027E | I19: 2028E | J19: 2029E | K19: 2030E
A21: 2. MOBILITY (driver principal del valor)
B22: GB growth (% YoY) | G22: 0.2 | H22: 0.16 | I22: 0.13 | J22: 0.11 | K22: 0.09
B23: Take Rate (Revenue / GB) | G23: 0.26 | H23: 0.27 | I23: 0.275 | J23: 0.28 | K23: 0.28
B24: Margen Op. de Mobility (% revenue) | G24: 0.3 | H24: 0.315 | I24: 0.325 | J24: 0.33 | K24: 0.335
A26: 3. DELIVERY (bloque secundario)
B27: GB growth (% YoY) | G27: 0.22 | H27: 0.18 | I27: 0.14 | J27: 0.11 | K27: 0.09
B28: Take Rate | G28: 0.195 | H28: 0.198 | I28: 0.2 | J28: 0.2 | K28: 0.2
B29: Margen Op. de Delivery (% revenue) | G29: 0.19 | H29: 0.205 | I29: 0.215 | J29: 0.22 | K29: 0.225
A31: 4. FREIGHT (modelar conservador)
B32: GB growth (% YoY) | G32: 0.05 | H32: 0.05 | I32: 0.04 | J32: 0.03 | K32: 0.03
B33: Take Rate (~100%) | G33: 1 | H33: 1 | I33: 1 | J33: 1 | K33: 1
B34: Margen Op. de Freight (% revenue) | G34: -0.015 | H34: 0 | I34: 0.005 | J34: 0.01 | K34: 0.015
A36: 5. CORPORATE OVERHEAD (driver de overhead dilution)
B37: Corporate cost (% Gross Bookings) | G37: 0.02 | H37: 0.018 | I37: 0.016 | J37: 0.015 | K37: 0.014
A39: 6. REINVERSION
B40: Sales-to-Capital ratio | D40: 5
B41: ΔWC / ΔRevenue | D41: -0.005
A43: 7. CAPTURA POR ACCION
B44: SBC % revenue | G44: 0.03 | H44: 0.028 | I44: 0.026 | J44: 0.025 | K44: 0.024
B45: Buyback neto (% acciones anual) | G45: 0.03 | H45: 0.025 | I45: 0.022 | J45: 0.02 | K45: 0.018
B46: Acciones diluidas iniciales (k) | D46: 2071391
A48: 8. BALANCE SHEET (Q1 2026, $M)
B49: Cash + equivalents | D49: 5558
...

Sheet Historico
A1: HISTORICO 2020-2025 / fuente: SEC 10-K, 8-K, 10-Q
B2: LEYENDA: | C2: AZUL+AMARILLO | D2: Input hardcoded (editable) | E2: AMARILLO FUERTE | F2: Input clave (driver de sensibilidad) | G2: NEGRO | H2: Formula (calculado) | I2: VERDE | J2: Link a otra hoja | K2: VERDE CLARO | L2: Resultado / output
D4: 2020A | E4: 2021A | F4: 2022A | G4: 2023A | H4: 2024A | I4: 2025A
A6: INCOME STATEMENT ($M, source: 10-K)
B7: Revenue | D7: 11139 | E7: 17455 | F7: 31877 | G7: 37281 | H7: 43978 | I7: 52017
B8: YoY growth % | E8: =E7/D7-1 -> 0.56701679 | F8: =F7/E7-1 -> 0.8262389 | G8: =G7/F7-1 -> 0.16952662 | H8: =H7/G7-1 -> 0.17963574 | I8: =I7/H7-1 -> 0.18279594
B10: Cost of revenue (excl. D&A) | D10: 5154 | E10: 9351 | F10: 18748 | G10: 21513 | H10: 26494 | I10: 31288
B11: Operations and support | D11: 1819 | E11: 1877 | F11: 2392 | G11: 2526 | H11: 2604 | I11: 2716
B12: Sales and marketing | D12: 3583 | E12: 4789 | F12: 4286 | G12: 4248 | H12: 4525 | I12: 5158
B13: Research and development | D13: 2205 | E13: 2054 | F13: 2666 | G13: 2989 | H13: 3104 | I13: 3399
B14: General and administrative | D14: 2666 | E14: 2316 | F14: 2421 | G14: 2436 | H14: 2789 | I14: 3179
B15: Depreciation and amortization | D15: 575 | E15: 902 | F15: 947 | G15: 823 | H15: 663 | I15: 712
B17: GAAP Income from Operations | D17: -4863 | E17: -3824 | F17: -1832 | G17: 1110 | H17: 2799 | I17: 5565
B18: GAAP Op margin % | D18: =D17/D7 -> -0.4365742 | E18: =E17/E7 -> -0.21907763 | F18: =F17/F7 -> -0.057470904 | G18: =G17/G7 -> 0.029773879 | H18: =H17/H7 -> 0.063645459 | I18: =I17/I7 -> 0.10698426
B19: Stock-based compensation (memo) | D19: 827 | E19: 1168 | F19: 1793 | G19: 1935 | H19: 1925 | I19: 1826
B20: SBC % revenue | D20: =D19/D7 -> 0.074243648 | E20: =E19/E7 -> 0.066914924 | F20: =F19/F7 -> 0.056247451 | G20: =G19/G7 -> 0.051903114 | H20: =H19/H7 -> 0.043771886 | I20: =I19/I7 -> 0.035103908
B22: Net Income (GAAP) | D22: -6768 | E22: -496 | F22: -9141 | G22: 1887 | H22: 9856 | I22: 10053
B23: EPS diluted ($) | D23: -3.86 | E23: -0.26 | F23: -4.49 | G23: 0.87 | H23: 4.56 | I23: 4.73
A25: ADJ EBITDA (Non-GAAP, source: company press releases)
B26: Adj EBITDA | D26: -2528 | E26: -774 | F26: 1713 | G26: 4052 | H26: 6484 | I26: 8730
B27: Adj EBITDA margin % | D27: =D26/D7 -> -0.22695035 | E27: =E26/E7 -> -0.044342595 | F27: =F26/F7 -> 0.053737805 | G27: =G26/G7 -> 0.10868807 | H27: =H26/H7 -> 0.14743736 | I27: =I26/I7 -> 0.16782975
A29: SEGMENT DATA ($M)
B30: Mobility — Gross Bookings | D30: 26553 | E30: 38713 | F30: 49669 | G30: 64995 | H30: 81763 | I30: 97497
B31: Mobility — Revenue | D31: 6089 | E31: 6953 | F31: 14000 | G31: 19783 | H31: 25086 | I31: 29670
B32: Take rate (Rev/GB) | D32: =D31/D30 -> 0.22931495 | E32: =E31/E30 -> 0.17960375 | F32: =F31/F30 -> 0.28186595 | G32: =G31/G30 -> 0.30437726 | H32: =H31/H30 -> 0.3068136 | I32: =I31/I30 -> 0.30431706
B33: Mobility — Adj EBITDA | D33: 1169 | E33: 1604 | F33: 3133 | G33: 5174 | H33: 6546 | I33: 7899
B35: Delivery — Gross Bookings | D35: 30227 | E35: 51635 | F35: 60048 | G35: 66331 | H35: 75144 | I35: 90864
B36: Delivery — Revenue | D36: 3904 | E36: 8362 | F36: 10905 | G36: 12204 | H36: 13745 | I36: 17248
B37: Take rate | D37: =D36/D35 -> 0.12915605 | E37: =E36/E35 -> 0.16194442 | F37: =F36/F35 -> 0.18160472 | G37: =G36/G35 -> 0.18398637 | H37: =H36/H35 -> 0.18291547 | I37: =I36/I35 -> 0.18982215
B38: Delivery — Adj EBITDA | D38: -873 | E38: -348 | F38: 553 | G38: 1502 | H38: 2516 | I38: 3572
B40: Freight — Gross Bookings | D40: 1051 | E40: 2132 | F40: 7058 | G40: 5245 | H40: 5277 | I40: 5141
B41: Freight — Revenue | D41: 1146 | E41: 2132 | F41: 6952 | G41: 5245 | H41: 5147 | I41: 5099
B42: Freight — Adj EBITDA | D42: -118 | E42: -147 | F42: -92 | G42: -224 | H42: -107 | I42: -33
B44: Corporate G&A + Platform R&D | D44: -2706 | E44: -1883 | F44: -1881 | G44: -2400 | H44: -2471 | I44: -2708
B46: Sum of segments + Corporate (check vs Adj EBITDA) | D46: =D33+D38+D42+D44 -> -2528 | E46: =E33+E38+E42+E44 -> -774 | F46: =F33+F38+F42+F44 -> 1713 | G46: =G33+G38+G42+G44 -> 4052 | H46: =H33+H38+H42+H44 -> 6484 | I46: =I33+I38+I42+I44 -> 8730
A48: BALANCE SHEET HISTORICAL ($M, source: 10-K)
B49: Total Assets | D49: 33252 | E49: 38774 | F49: 32109 | G49: 38699 | H49: 51244 | I49: 61802
B50: Total Stockholders' Equity (UBER) | D50: 12266 | E50: 14458 | F50: 7340 | G50: 11249 | H50: 21558 | I50: 27041
B51: Total Equity (incl. NCI) | D51: 12721 | E51: 14997 | F51: 7656 | G51: 11614 | H51: 22383 | I51: 27918
B52: Long-term Debt | D52: 7561 | E52: 9276 | F52: 9265 | G52: 9456 | H52: 10579 | I52: 10521
...

Sheet Modelo
A1: MODELO DE OPERACIONES + FCFF + VALORACION / sensibilidades a la derecha
B2: LEYENDA: | C2: AZUL+AMARILLO | D2: Input hardcoded (editable) | E2: AMARILLO FUERTE | F2: Input clave (driver de sensibilidad) | G2: NEGRO | H2: Formula (calculado) | I2: VERDE | J2: Link a otra hoja | K2: VERDE CLARO | L2: Resultado / output
D4: 2024A | E4: 2025A | F4: 2026E | G4: 2027E | H4: 2028E | I4: 2029E | J4: 2030E
L5: (Sensibilidad Mobility — pendiente posicion)
A6: A. MOBILITY (driver principal del valor) | L6: Sens A. Mobility Margin × Take Rate (precio implicito $)
B7: Gross Bookings ($M) | D7: =Historico!H30 -> 81763 | E7: =Historico!I30 -> 97497 | F7: =E7*(1+Hipotesis!G22) -> 116996.4 | G7: =F7*(1+Hipotesis!H22) -> 135715.82 | H7: =G7*(1+Hipotesis!I22) -> 153358.88 | I7: =H7*(1+Hipotesis!J22) -> 170228.36 | J7: =I7*(1+Hipotesis!K22) -> 185548.91 | L7: Op Margin ↓ Take Rate →
B8: YoY % | E8: =E7/D7-1 -> 0.19243423 | F8: =F7/E7-1 -> 0.2 | G8: =G7/F7-1 -> 0.16 | H8: =H7/G7-1 -> 0.13 | I8: =I7/H7-1 -> 0.11 | J8: =J7/I7-1 -> 0.09 | M8: 0.25 | N8: 0.26 | O8: 0.27 | P8: 0.28 | Q8: 0.29 | R8: 0.3
L9: 0.27 | M9: =(($D$82-$J$81+(((((($J$7*M$8)*$L9)+($J$62-$J$15))*(1-Hipotesis!$D$10))-((($J$67-$J$11+($J$7*M$8))-$I$67)/Hipotesis!$D$40))/(1+Hipotesis!$D$14)^5))+((((((($J$7*M$8)*$L9)+($J$62-$J$15))*(1-Hipotesis!$D$10))-((($J$67-$J$11+($J$7*M$8))-$I$67)/Hipotesis!$D$40))*(1+Hipotesis!$D$15)/(Hipotesis!$D$14-Hipotesis!$D$15))/(1+Hipotesis!$D$14)^5)+(Hipotesis!$D$49+Hipotesis!$D$50-Hipotesis!$D$51+Hipotesis!$D$52+Hipotesis!$D$53-Hipotesis!$D$54))/Hipotesis!$D$46*1000 -> 62.001213 | N9: =(($D$82-$J$81+(((((($J$7*N$8)*$L9)+($J$62-$J$15))*(1-Hipotesis!$D$10))-((($J$67-$J$11+($J$7*N$8))-$I$67)/Hipotesis!$D$40))/(1+Hipotesis!$D$14)^5))+((((((($J$7*N$8)*$L9)+($J$62-$J$15))*(1-Hipotesis!$D$10))-((($J$67-$J$11+($J$7*N$8))-$I$67)/Hipotesis!$D$40))*(1+Hipotesis!$D$15)/(Hipotesis!$D$14-Hipotesis!$D$15))/(1+Hipotesis!$D$14)^5)+(Hipotesis!$D$49+Hipotesis!$D$50-Hipotesis!$D$51+Hipotesis!$D$52+Hipotesis!$D$53-Hipotesis!$D$54))/Hipotesis!$D$46*1000 -> 62.081384 | O9: =(($D$82-$J$81+(((((($J$7*O$8)*$L9)+($J$62-$J$15))*(1-Hipotesis!$D$10))-((($J$67-$J$11+($J$7*O$8))-$I$67)/Hipotesis!$D$40))/(1+Hipotesis!$D$14)^5))+((((((($J$7*O$8)*$L9)+($J$62-$J$15))*(1-Hipotesis!$D$10))-((($J$67-$J$11+($J$7*O$8))-$I$67)/Hipotesis!$D$40))*(1+Hipotesis!$D$15)/(Hipotesis!$D$14-Hipotesis!$D$15))/(1+Hipotesis!$D$14)^5)+(Hipotesis!$D$49+Hipotesis!$D$50-Hipotesis!$D$51+Hipotesis!$D$52+Hipotesis!$D$53-Hipotesis!$D$54))/Hipotesis!$D$46*1000 -> 62.161556 | P9: =(($D$82-$J$81+(((((($J$7*P$8)*$L9)+($J$62-$J$15))*(1-Hipotesis!$D$10))-((($J$67-$J$11+($J$7*P$8))-$I$67)/Hipotesis!$D$40))/(1+Hipotesis!$D$14)^5))+((((((($J$7*P$8)*$L9)+($J$62-$J$15))*(1-Hipotesis!$D$10))-((($J$67-$J$11+($J$7*P$8))-$I$67)/Hipotesis!$D$40))*(1+Hipotesis!$D$15)/(Hipotesis!$D$14-Hipotesis!$D$15))/(1+Hipotesis!$D$14)^5)+(Hipotesis!$D$49+Hipotesis!$D$50-Hipotesis!$D$51+Hipotesis!$D$52+Hipotesis!$D$53-Hipotesis!$D$54))/Hipotesis!$D$46*1000 -> 62.241728 | Q9: =(($D$82-$J$81+(((((($J$7*Q$8)*$L9)+($J$62-$J$15))*(1-Hipotesis!$D$10))-((($J$67-$J$11+($J$7*Q$8))-$I$67)/Hipotesis!$D$40))/(1+Hipotesis!$D$14)^5))+((((((($J$7*Q$8)*$L9)+($J$62-$J$15))*(1-Hipotesis!$D$10))-((($J$67-$J$11+($J$7*Q$8))-$I$67)/Hipotesis!$D$40))*(1+Hipotesis!$D$15)/(Hipotesis!$D$14-Hipotesis!$D$15))/(1+Hipotesis!$D$14)^5)+(Hipotesis!$D$49+Hipotesis!$D$50-Hipotesis!$D$51+Hipotesis!$D$52+Hipotesis!$D$53-Hipotesis!$D$54))/Hipotesis!$D$46*1000 -> 62.3219 | R9: =(($D$82-$J$81+(((((($J$7*R$8)*$L9)+($J$62-$J$15))*(1-Hipotesis!$D$10))-((($J$67-$J$11+($J$7*R$8))-$I$67)/Hipotesis!$D$40))/(1+Hipotesis!$D$14)^5))+((((((($J$7*R$8)*$L9)+($J$62-$J$15))*(1-Hipotesis!$D$10))-((($J$67-$J$11+($J$7*R$8))-$I$67)/Hipotesis!$D$40))*(1+Hipotesis!$D$15)/(Hipotesis!$D$14-Hipotesis!$D$15))/(1+Hipotesis!$D$14)^5)+(Hipotesis!$D$49+Hipotesis!$D$50-Hipotesis!$D$51+Hipotesis!$D$52+Hipotesis!$D$53-Hipotesis!$D$54))/Hipotesis!$D$46*1000 -> 62.402072
B10: Take Rate (Rev/GB) | D10: =Historico!H32 -> 0.3068136 | E10: =Historico!I32 -> 0.30431706 | F10: =Hipotesis!G23 -> 0.26 | G10: =Hipotesis!H23 -> 0.27 | H10: =Hipotesis!I23 -> 0.275 | I10: =Hipotesis!J23 -> 0.28 | J10: =Hipotesis!K23 -> 0.28 | L10: 0.29 | M10: =(($D$82-$J$81+(((((($J$7*M$8)*$L10)+($J$62-$J$15))*(1-Hipotesis!$D$10))-((($J$67-$J$11+($J$7*M$8))-$I$67)/Hipotesis!$D$40))/(1+Hipotesis!$D$14)^5))+((((((($J$7*M$8)*$L10)+($J$62-$J$15))*(1-Hipotesis!$D$10))-((($J$67-$J$11+($J$7*M$8))-$I$67)/Hipotesis!$D$40))*(1+Hipotesis!$D$15)/(Hipotesis!$D$14-Hipotesis!$D$15))/(1+Hipotesis!$D$14)^5)+(Hipotesis!$D$49+Hipotesis!$D$50-Hipotesis!$D$51+Hipotesis!$D$52+Hipotesis!$D$53-Hipotesis!$D$54))/Hipotesis!$D$46*1000 -> 64.950933 | N10: =(($D$82-$J$81+(((((($J$7*N$8)*$L10)+($J$62-$J$15))*(1-Hipotesis!$D$10))-((($J$67-$J$11+($J$7*N$8))-$I$67)/Hipotesis!$D$40))/(1+Hipotesis!$D$14)^5))+((((((($J$7*N$8)*$L10)+($J$62-$J$15))*(1-Hipotesis!$D$10))-((($J$67-$J$11+($J$7*N$8))-$I$67)/Hipotesis!$D$40))*(1+Hipotesis!$D$15)/(Hipotesis!$D$14-Hipotesis!$D$15))/(1+Hipotesis!$D$14)^5)+(Hipotesis!$D$49+Hipotesis!$D$50-Hipotesis!$D$51+Hipotesis!$D$52+Hipotesis!$D$53-Hipotesis!$D$54))/Hipotesis!$D$46*1000 -> 65.149093 | O10: =(($D$82-$J$81+(((((($J$7*O$8)*$L10)+($J$62-$J$15))*(1-Hipotesis!$D$10))-((($J$67-$J$11+($J$7*O$8))-$I$67)/Hipotesis!$D$40))/(1+Hipotesis!$D$14)^5))+((((((($J$7*O$8)*$L10)+($J$62-$J$15))*(1-Hipotesis!$D$10))-((($J$67-$J$11+($J$7*O$8))-$I$67)/Hipotesis!$D$40))*(1+Hipotesis!$D$15)/(Hipotesis!$D$14-Hipotesis!$D$15))/(1+Hipotesis!$D$14)^5)+(Hipotesis!$D$49+Hipotesis!$D$50-Hipotesis!$D$51+Hipotesis!$D$52+Hipotesis!$D$53-Hipotesis!$D$54))/Hipotesis!$D$46*1000 -> 65.347254 | P10: =(($D$82-$J$81+(((((($J$7*P$8)*$L10)+($J$62-$J$15))*(1-Hipotesis!$D$10))-((($J$67-$J$11+($J$7*P$8))-$I$67)/Hipotesis!$D$40))/(1+Hipotesis!$D$14)^5))+((((((($J$7*P$8)*$L10)+($J$62-$J$15))*(1-Hipotesis!$D$10))-((($J$67-$J$11+($J$7*P$8))-$I$67)/Hipotesis!$D$40))*(1+Hipotesis!$D$15)/(Hipotesis!$D$14-Hipotesis!$D$15))/(1+Hipotesis!$D$14)^5)+(Hipotesis!$D$49+Hipotesis!$D$50-Hipotesis!$D$51+Hipotesis!$D$52+Hipotesis!$D$53-Hipotesis!$D$54))/Hipotesis!$D$46*1000 -> 65.545415 | Q10: =(($D$82-$J$81+(((((($J$7*Q$8)*$L10)+($J$62-$J$15))*(1-Hipotesis!$D$10))-((($J$67-$J$11+($J$7*Q$8))-$I$67)/Hipotesis!$D$40))/(1+Hipotesis!$D$14)^5))+((((((($J$7*Q$8)*$L10)+($J$62-$J$15))*(1-Hipotesis!$D$10))-((($J$67-$J$11+($J$7*Q$8))-$I$67)/Hipotesis!$D$40))*(1+Hipotesis!$D$15)/(Hipotesis!$D$14-Hipotesis!$D$15))/(1+Hipotesis!$D$14)^5)+(Hipotesis!$D$49+Hipotesis!$D$50-Hipotesis!$D$51+Hipotesis!$D$52+Hipotesis!$D$53-Hipotesis!$D$54))/Hipotesis!$D$46*1000 -> 65.743575 | R10: =(($D$82-$J$81+(((((($J$7*R$8)*$L10)+($J$62-$J$15))*(1-Hipotesis!$D$10))-((($J$67-$J$11+($J$7*R$8))-$I$67)/Hipotesis!$D$40))/(1+Hipotesis!$D$14)^5))+((((((($J$7*R$8)*$L10)+($J$62-$J$15))*(1-Hipotesis!$D$10))-((($J$67-$J$11+($J$7*R$8))-$I$67)/Hipotesis!$D$40))*(1+Hipotesis!$D$15)/(Hipotesis!$D$14-Hipotesis!$D$15))/(1+Hipotesis!$D$14)^5)+(Hipotesis!$D$49+Hipotesis!$D$50-Hipotesis!$D$51+Hipotesis!$D$52+Hipotesis!$D$53-Hipotesis!$D$54))/Hipotesis!$D$46*1000 -> 65.941736
B11: Revenue ($M) | D11: =D7*D10 -> 25086 | E11: =E7*E10 -> 29670 | F11: =F7*F10 -> 30419.064 | G11: =G7*G10 -> 36643.272 | H11: =H7*H10 -> 42173.692 | I11: =I7*I10 -> 47663.94 | J11: =J7*J10 -> 51953.695 | L11: 0.31 | M11: =(($D$82-$J$81+(((((($J$7*M$8)*$L11)+($J$62-$J$15))*(1-Hipotesis!$D$10))-((($J$67-$J$11+($J$7*M$8))-$I$67)/Hipotesis!$D$40))/(1+Hipotesis!$D$14)^5))+((((((($J$7*M$8)*$L11)+($J$62-$J$15))*(1-Hipotesis!$D$10))-((($J$67-$J$11+($J$7*M$8))-$I$67)/Hipotesis!$D$40))*(1+Hipotesis!$D$15)/(Hipotesis!$D$14-Hipotesis!$D$15))/(1+Hipotesis!$D$14)^5)+(Hipotesis!$D$49+Hipotesis!$D$50-Hipotesis!$D$51+Hipotesis!$D$52+Hipotesis!$D$53-Hipotesis!$D$54))/Hipotesis!$D$46*1000 -> 67.900652 | N11: =(($D$82-$J$81+(((((($J$7*N$8)*$L11)+($J$62-$J$15))*(1-Hipotesis!$D$10))-((($J$67-$J$11+($J$7*N$8))-$I$67)/Hipotesis!$D$40))/(1+Hipotesis!$D$14)^5))+((((((($J$7*N$8)*$L11)+($J$62-$J$15))*(1-Hipotesis!$D$10))-((($J$67-$J$11+($J$7*N$8))-$I$67)/Hipotesis!$D$40))*(1+Hipotesis!$D$15)/(Hipotesis!$D$14-Hipotesis!$D$15))/(1+Hipotesis!$D$14)^5)+(Hipotesis!$D$49+Hipotesis!$D$50-Hipotesis!$D$51+Hipotesis!$D$52+Hipotesis!$D$53-Hipotesis!$D$54))/Hipotesis!$D$46*1000 -> 68.216802 | O11: =(($D$82-$J$81+(((((($J$7*O$8)*$L11)+($J$62-$J$15))*(1-Hipotesis!$D$10))-((($J$67-$J$11+($J$7*O$8))-$I$67)/Hipotesis!$D$40))/(1+Hipotesis!$D$14)^5))+((((((($J$7*O$8)*$L11)+($J$62-$J$15))*(1-Hipotesis!$D$10))-((($J$67-$J$11+($J$7*O$8))-$I$67)/Hipotesis!$D$40))*(1+Hipotesis!$D$15)/(Hipotesis!$D$14-Hipotesis!$D$15))/(1+Hipotesis!$D$14)^5)+(Hipotesis!$D$49+Hipotesis!$D$50-Hipotesis!$D$51+Hipotesis!$D$52+Hipotesis!$D$53-Hipotesis!$D$54))/Hipotesis!$D$46*1000 -> 68.532951 | P11: =(($D$82-$J$81+(((((($J$7*P$8)*$L11)+($J$62-$J$15))*(1-Hipotesis!$D$10))-((($J$67-$J$11+($J$7*P$8))-$I$67)/Hipotesis!$D$40))/(1+Hipotesis!$D$14)^5))+((((((($J$7*P$8)*$L11)+($J$62-$J$15))*(1-Hipotesis!$D$10))-((($J$67-$J$11+($J$7*P$8))-$I$67)/Hipotesis!$D$40))*(1+Hipotesis!$D$15)/(Hipotesis!$D$14-Hipotesis!$D$15))/(1+Hipotesis!$D$14)^5)+(Hipotesis!$D$49+Hipotesis!$D$50-Hipotesis!$D$51+Hipotesis!$D$52+Hipotesis!$D$53-Hipotesis!$D$54))/Hipotesis!$D$46*1000 -> 68.849101 | Q11: =(($D$82-$J$81+(((((($J$7*Q$8)*$L11)+($J$62-$J$15))*(1-Hipotesis!$D$10))-((($J$67-$J$11+($J$7*Q$8))-$I$67)/Hipotesis!$D$40))/(1+Hipotesis!$D$14)^5))+((((((($J$7*Q$8)*$L11)+($J$62-$J$15))*(1-Hipotesis!$D$10))-((($J$67-$J$11+($J$7*Q$8))-$I$67)/Hipotesis!$D$40))*(1+Hipotesis!$D$15)/(Hipotesis!$D$14-Hipotesis!$D$15))/(1+Hipotesis!$D$14)^5)+(Hipotesis!$D$49+Hipotesis!$D$50-Hipotesis!$D$51+Hipotesis!$D$52+Hipotesis!$D$53-Hipotesis!$D$54))/Hipotesis!$D$46*1000 -> 69.16525 | R11: =(($D$82-$J$81+(((((($J$7*R$8)*$L11)+($J$62-$J$15))*(1-Hipotesis!$D$10))-((($J$67-$J$11+($J$7*R$8))-$I$67)/Hipotesis!$D$40))/(1+Hipotesis!$D$14)^5))+((((((($J$7*R$8)*$L11)+($J$62-$J$15))*(1-Hipotesis!$D$10))-((($J$67-$J$11+($J$7*R$8))-$I$67)/Hipotesis!$D$40))*(1+Hipotesis!$D$15)/(Hipotesis!$D$14-Hipotesis!$D$15))/(1+Hipotesis!$D$14)^5)+(Hipotesis!$D$49+Hipotesis!$D$50-Hipotesis!$D$51+Hipotesis!$D$52+Hipotesis!$D$53-Hipotesis!$D$54))/Hipotesis!$D$46*1000 -> 69.4814
B12: YoY % | E12: =E11/D11-1 -> 0.1827314 | F12: =F11/E11-1 -> 0.025246512 | G12: =G11/F11-1 -> 0.20461538 | H12: =H11/G11-1 -> 0.15092593 | I12: =I11/H11-1 -> 0.13018182 | J12: =J11/I11-1 -> 0.09 | L12: 0.33 | M12: =(($D$82-$J$81+(((((($J$7*M$8)*$L12)+($J$62-$J$15))*(1-Hipotesis!$D$10))-((($J$67-$J$11+($J$7*M$8))-$I$67)/Hipotesis!$D$40))/(1+Hipotesis!$D$14)^5))+((((((($J$7*M$8)*$L12)+($J$62-$J$15))*(1-Hipotesis!$D$10))-((($J$67-$J$11+($J$7*M$8))-$I$67)/Hipotesis!$D$40))*(1+Hipotesis!$D$15)/(Hipotesis!$D$14-Hipotesis!$D$15))/(1+Hipotesis!$D$14)^5)+(Hipotesis!$D$49+Hipotesis!$D$50-Hipotesis!$D$51+Hipotesis!$D$52+Hipotesis!$D$53-Hipotesis!$D$54))/Hipotesis!$D$46*1000 -> 70.850372 | N12: =(($D$82-$J$81+(((((($J$7*N$8)*$L12)+($J$62-$J$15))*(1-Hipotesis!$D$10))-((($J$67-$J$11+($J$7*N$8))-$I$67)/Hipotesis!$D$40))/(1+Hipotesis!$D$14)^5))+((((((($J$7*N$8)*$L12)+($J$62-$J$15))*(1-Hipotesis!$D$10))-((($J$67-$J$11+($J$7*N$8))-$I$67)/Hipotesis!$D$40))*(1+Hipotesis!$D$15)/(Hipotesis!$D$14-Hipotesis!$D$15))/(1+Hipotesis!$D$14)^5)+(Hipotesis!$D$49+Hipotesis!$D$50-Hipotesis!$D$51+Hipotesis!$D$52+Hipotesis!$D$53-Hipotesis!$D$54))/Hipotesis!$D$46*1000 -> 71.284511 | O12: =(($D$82-$J$81+(((((($J$7*O$8)*$L12)+($J$62-$J$15))*(1-Hipotesis!$D$10))-((($J$67-$J$11+($J$7*O$8))-$I$67)/Hipotesis!$D$40))/(1+Hipotesis!$D$14)^5))+((((((($J$7*O$8)*$L12)+($J$62-$J$15))*(1-Hipotesis!$D$10))-((($J$67-$J$11+($J$7*O$8))-$I$67)/Hipotesis!$D$40))*(1+Hipotesis!$D$15)/(Hipotesis!$D$14-Hipotesis!$D$15))/(1+Hipotesis!$D$14)^5)+(Hipotesis!$D$49+Hipotesis!$D$50-Hipotesis!$D$51+Hipotesis!$D$52+Hipotesis!$D$53-Hipotesis!$D$54))/Hipotesis!$D$46*1000 -> 71.718649 | P12: =(($D$82-$J$81+(((((($J$7*P$8)*$L12)+($J$62-$J$15))*(1-Hipotesis!$D$10))-((($J$67-$J$11+($J$7*P$8))-$I$67)/Hipotesis!$D$40))/(1+Hipotesis!$D$14)^5))+((((((($J$7*P$8)*$L12)+($J$62-$J$15))*(1-Hipotesis!$D$10))-((($J$67-$J$11+($J$7*P$8))-$I$67)/Hipotesis!$D$40))*(1+Hipotesis!$D$15)/(Hipotesis!$D$14-Hipotesis!$D$15))/(1+Hipotesis!$D$14)^5)+(Hipotesis!$D$49+Hipotesis!$D$50-Hipotesis!$D$51+Hipotesis!$D$52+Hipotesis!$D$53-Hipotesis!$D$54))/Hipotesis!$D$46*1000 -> 72.152787 | Q12: =(($D$82-$J$81+(((((($J$7*Q$8)*$L12)+($J$62-$J$15))*(1-Hipotesis!$D$10))-((($J$67-$J$11+($J$7*Q$8))-$I$67)/Hipotesis!$D$40))/(1+Hipotesis!$D$14)^5))+((((((($J$7*Q$8)*$L12)+($J$62-$J$15))*(1-Hipotesis!$D$10))-((($J$67-$J$11+($J$7*Q$8))-$I$67)/Hipotesis!$D$40))*(1+Hipotesis!$D$15)/(Hipotesis!$D$14-Hipotesis!$D$15))/(1+Hipotesis!$D$14)^5)+(Hipotesis!$D$49+Hipotesis!$D$50-Hipotesis!$D$51+Hipotesis!$D$52+Hipotesis!$D$53-Hipotesis!$D$54))/Hipotesis!$D$46*1000 -> 72.586925 | R12: =(($D$82-$J$81+(((((($J$7*R$8)*$L12)+($J$62-$J$15))*(1-Hipotesis!$D$10))-((($J$67-$J$11+($J$7*R$8))-$I$67)/Hipotesis!$D$40))/(1+Hipotesis!$D$14)^5))+((((((($J$7*R$8)*$L12)+($J$62-$J$15))*(1-Hipotesis!$D$10))-((($J$67-$J$11+($J$7*R$8))-$I$67)/Hipotesis!$D$40))*(1+Hipotesis!$D$15)/(Hipotesis!$D$14-Hipotesis!$D$15))/(1+Hipotesis!$D$14)^5)+(Hipotesis!$D$49+Hipotesis!$D$50-Hipotesis!$D$51+Hipotesis!$D$52+Hipotesis!$D$53-Hipotesis!$D$54))/Hipotesis!$D$46*1000 -> 73.021064
L13: 0.35 | M13: =(($D$82-$J$81+(((((($J$7*M$8)*$L13)+($J$62-$J$15))*(1-Hipotesis!$D$10))-((($J$67-$J$11+($J$7*M$8))-$I$67)/Hipotesis!$D$40))/(1+Hipotesis!$D$14)^5))+((((((($J$7*M$8)*$L13)+($J$62-$J$15))*(1-Hipotesis!$D$10))-((($J$67-$J$11+($J$7*M$8))-$I$67)/Hipotesis!$D$40))*(1+Hipotesis!$D$15)/(Hipotesis!$D$14-Hipotesis!$D$15))/(1+Hipotesis!$D$14)^5)+(Hipotesis!$D$49+Hipotesis!$D$50-Hipotesis!$D$51+Hipotesis!$D$52+Hipotesis!$D$53-Hipotesis!$D$54))/Hipotesis!$D$46*1000 -> 73.800092 | N13: =(($D$82-$J$81+(((((($J$7*N$8)*$L13)+($J$62-$J$15))*(1-Hipotesis!$D$10))-((($J$67-$J$11+($J$7*N$8))-$I$67)/Hipotesis!$D$40))/(1+Hipotesis!$D$14)^5))+((((((($J$7*N$8)*$L13)+($J$62-$J$15))*(1-Hipotesis!$D$10))-((($J$67-$J$11+($J$7*N$8))-$I$67)/Hipotesis!$D$40))*(1+Hipotesis!$D$15)/(Hipotesis!$D$14-Hipotesis!$D$15))/(1+Hipotesis!$D$14)^5)+(Hipotesis!$D$49+Hipotesis!$D$50-Hipotesis!$D$51+Hipotesis!$D$52+Hipotesis!$D$53-Hipotesis!$D$54))/Hipotesis!$D$46*1000 -> 74.352219 | O13: =(($D$82-$J$81+(((((($J$7*O$8)*$L13)+($J$62-$J$15))*(1-Hipotesis!$D$10))-((($J$67-$J$11+($J$7*O$8))-$I$67)/Hipotesis!$D$40))/(1+Hipotesis!$D$14)^5))+((((((($J$7*O$8)*$L13)+($J$62-$J$15))*(1-Hipotesis!$D$10))-((($J$67-$J$11+($J$7*O$8))-$I$67)/Hipotesis!$D$40))*(1+Hipotesis!$D$15)/(Hipotesis!$D$14-Hipotesis!$D$15))/(1+Hipotesis!$D$14)^5)+(Hipotesis!$D$49+Hipotesis!$D$50-Hipotesis!$D$51+Hipotesis!$D$52+Hipotesis!$D$53-Hipotesis!$D$54))/Hipotesis!$D$46*1000 -> 74.904346 | P13: =(($D$82-$J$81+(((((($J$7*P$8)*$L13)+($J$62-$J$15))*(1-Hipotesis!$D$10))-((($J$67-$J$11+($J$7*P$8))-$I$67)/Hipotesis!$D$40))/(1+Hipotesis!$D$14)^5))+((((((($J$7*P$8)*$L13)+($J$62-$J$15))*(1-Hipotesis!$D$10))-((($J$67-$J$11+($J$7*P$8))-$I$67)/Hipotesis!$D$40))*(1+Hipotesis!$D$15)/(Hipotesis!$D$14-Hipotesis!$D$15))/(1+Hipotesis!$D$14)^5)+(Hipotesis!$D$49+Hipotesis!$D$50-Hipotesis!$D$51+Hipotesis!$D$52+Hipotesis!$D$53-Hipotesis!$D$54))/Hipotesis!$D$46*1000 -> 75.456474 | Q13: =(($D$82-$J$81+(((((($J$7*Q$8)*$L13)+($J$62-$J$15))*(1-Hipotesis!$D$10))-((($J$67-$J$11+($J$7*Q$8))-$I$67)/Hipotesis!$D$40))/(1+Hipotesis!$D$14)^5))+((((((($J$7*Q$8)*$L13)+($J$62-$J$15))*(1-Hipotesis!$D$10))-((($J$67-$J$11+($J$7*Q$8))-$I$67)/Hipotesis!$D$40))*(1+Hipotesis!$D$15)/(Hipotesis!$D$14-Hipotesis!$D$15))/(1+Hipotesis!$D$14)^5)+(Hipotesis!$D$49+Hipotesis!$D$50-Hipotesis!$D$51+Hipotesis!$D$52+Hipotesis!$D$53-Hipotesis!$D$54))/Hipotesis!$D$46*1000 -> 76.008601 | R13: =(($D$82-$J$81+(((((($J$7*R$8)*$L13)+($J$62-$J$15))*(1-Hipotesis!$D$10))-((($J$67-$J$11+($J$7*R$8))-$I$67)/Hipotesis!$D$40))/(1+Hipotesis!$D$14)^5))+((((((($J$7*R$8)*$L13)+($J$62-$J$15))*(1-Hipotesis!$D$10))-((($J$67-$J$11+($J$7*R$8))-$I$67)/Hipotesis!$D$40))*(1+Hipotesis!$D$15)/(Hipotesis!$D$14-Hipotesis!$D$15))/(1+Hipotesis!$D$14)^5)+(Hipotesis!$D$49+Hipotesis!$D$50-Hipotesis!$D$51+Hipotesis!$D$52+Hipotesis!$D$53-Hipotesis!$D$54))/Hipotesis!$D$46*1000 -> 76.560728
B14: Op Margin (% revenue) | D14: 0.232 | E14: 0.241 | F14: =Hipotesis!G24 -> 0.3 | G14: =Hipotesis!H24 -> 0.315 | H14: =Hipotesis!I24 -> 0.325 | I14: =Hipotesis!J24 -> 0.33 | J14: =Hipotesis!K24 -> 0.335 | L14: 0.37 | M14: =(($D$82-$J$81+(((((($J$7*M$8)*$L14)+($J$62-$J$15))*(1-Hipotesis!$D$10))-((($J$67-$J$11+($J$7*M$8))-$I$67)/Hipotesis!$D$40))/(1+Hipotesis!$D$14)^5))+((((((($J$7*M$8)*$L14)+($J$62-$J$15))*(1-Hipotesis!$D$10))-((($J$67-$J$11+($J$7*M$8))-$I$67)/Hipotesis!$D$40))*(1+Hipotesis!$D$15)/(Hipotesis!$D$14-Hipotesis!$D$15))/(1+Hipotesis!$D$14)^5)+(Hipotesis!$D$49+Hipotesis!$D$50-Hipotesis!$D$51+Hipotesis!$D$52+Hipotesis!$D$53-Hipotesis!$D$54))/Hipotesis!$D$46*1000 -> 76.749812 | N14: =(($D$82-$J$81+(((((($J$7*N$8)*$L14)+($J$62-$J$15))*(1-Hipotesis!$D$10))-((($J$67-$J$11+($J$7*N$8))-$I$67)/Hipotesis!$D$40))/(1+Hipotesis!$D$14)^5))+((((((($J$7*N$8)*$L14)+($J$62-$J$15))*(1-Hipotesis!$D$10))-((($J$67-$J$11+($J$7*N$8))-$I$67)/Hipotesis!$D$40))*(1+Hipotesis!$D$15)/(Hipotesis!$D$14-Hipotesis!$D$15))/(1+Hipotesis!$D$14)^5)+(Hipotesis!$D$49+Hipotesis!$D$50-Hipotesis!$D$51+Hipotesis!$D$52+Hipotesis!$D$53-Hipotesis!$D$54))/Hipotesis!$D$46*1000 -> 77.419928 | O14: =(($D$82-$J$81+(((((($J$7*O$8)*$L14)+($J$62-$J$15))*(1-Hipotesis!$D$10))-((($J$67-$J$11+($J$7*O$8))-$I$67)/Hipotesis!$D$40))/(1+Hipotesis!$D$14)^5))+((((((($J$7*O$8)*$L14)+($J$62-$J$15))*(1-Hipotesis!$D$10))-((($J$67-$J$11+($J$7*O$8))-$I$67)/Hipotesis!$D$40))*(1+Hipotesis!$D$15)/(Hipotesis!$D$14-Hipotesis!$D$15))/(1+Hipotesis!$D$14)^5)+(Hipotesis!$D$49+Hipotesis!$D$50-Hipotesis!$D$51+Hipotesis!$D$52+Hipotesis!$D$53-Hipotesis!$D$54))/Hipotesis!$D$46*1000 -> 78.090044 | P14: =(($D$82-$J$81+(((((($J$7*P$8)*$L14)+($J$62-$J$15))*(1-Hipotesis!$D$10))-((($J$67-$J$11+($J$7*P$8))-$I$67)/Hipotesis!$D$40))/(1+Hipotesis!$D$14)^5))+((((((($J$7*P$8)*$L14)+($J$62-$J$15))*(1-Hipotesis!$D$10))-((($J$67-$J$11+($J$7*P$8))-$I$67)/Hipotesis!$D$40))*(1+Hipotesis!$D$15)/(Hipotesis!$D$14-Hipotesis!$D$15))/(1+Hipotesis!$D$14)^5)+(Hipotesis!$D$49+Hipotesis!$D$50-Hipotesis!$D$51+Hipotesis!$D$52+Hipotesis!$D$53-Hipotesis!$D$54))/Hipotesis!$D$46*1000 -> 78.76016 | Q14: =(($D$82-$J$81+(((((($J$7*Q$8)*$L14)+($J$62-$J$15))*(1-Hipotesis!$D$10))-((($J$67-$J$11+($J$7*Q$8))-$I$67)/Hipotesis!$D$40))/(1+Hipotesis!$D$14)^5))+((((((($J$7*Q$8)*$L14)+($J$62-$J$15))*(1-Hipotesis!$D$10))-((($J$67-$J$11+($J$7*Q$8))-$I$67)/Hipotesis!$D$40))*(1+Hipotesis!$D$15)/(Hipotesis!$D$14-Hipotesis!$D$15))/(1+Hipotesis!$D$14)^5)+(Hipotesis!$D$49+Hipotesis!$D$50-Hipotesis!$D$51+Hipotesis!$D$52+Hipotesis!$D$53-Hipotesis!$D$54))/Hipotesis!$D$46*1000 -> 79.430276 | R14: =(($D$82-$J$81+(((((($J$7*R$8)*$L14)+($J$62-$J$15))*(1-Hipotesis!$D$10))-((($J$67-$J$11+($J$7*R$8))-$I$67)/Hipotesis!$D$40))/(1+Hipotesis!$D$14)^5))+((((((($J$7*R$8)*$L14)+($J$62-$J$15))*(1-Hipotesis!$D$10))-((($J$67-$J$11+($J$7*R$8))-$I$67)/Hipotesis!$D$40))*(1+Hipotesis!$D$15)/(Hipotesis!$D$14-Hipotesis!$D$15))/(1+Hipotesis!$D$14)^5)+(Hipotesis!$D$49+Hipotesis!$D$50-Hipotesis!$D$51+Hipotesis!$D$52+Hipotesis!$D$53-Hipotesis!$D$54))/Hipotesis!$D$46*1000 -> 80.100392
B15: Segment Op Income ($M) | D15: =D11*D14 -> 5819.952 | E15: =E11*E14 -> 7150.47 | F15: =F11*F14 -> 9125.7192 | G15: =G11*G14 -> 11542.631 | H15: =H11*H14 -> 13706.45 | I15: =I11*I14 -> 15729.1 | J15: =J11*J14 -> 17404.488
B16: % de GB (margen sobre actividad) | D16: =D15/D7 -> 0.071180754 | E16: =E15/E7 -> 0.07334041 | F16: =F15/F7 -> 0.078 | G16: =G15/G7 -> 0.08505 | H16: =H15/H7 -> 0.089375 | I16: =I15/I7 -> 0.0924 | J16: =J15/J7 -> 0.0938 | L16: Caso base aprox: TR 28%, margen 33%. El resto de drivers se mantiene en base.
A18: B. DELIVERY (bloque secundario)
B19: Gross Bookings ($M) | D19: =Historico!H35 -> 75144 | E19: =Historico!I35 -> 90864 | F19: =E19*(1+Hipotesis!G27) -> 110854.08 | G19: =F19*(1+Hipotesis!H27) -> 130807.81 | H19: =G19*(1+Hipotesis!I27) -> 149120.91 | I19: =H19*(1+Hipotesis!J27) -> 165524.21 | J19: =I19*(1+Hipotesis!K27) -> 180421.39
B20: YoY % | E20: =E19/D19-1 -> 0.20919834 | F20: =F19/E19-1 -> 0.22 | G20: =G19/F19-1 -> 0.18 | H20: =H19/G19-1 -> 0.14 | I20: =I19/H19-1 -> 0.11 | J20: =J19/I19-1 -> 0.09
B22: Take Rate | D22: =Historico!H37 -> 0.18291547 | E22: =Historico!I37 -> 0.18982215 | F22: =Hipotesis!G28 -> 0.195 | G22: =Hipotesis!H28 -> 0.198 | H22: =Hipotesis!I28 -> 0.2 | I22: =Hipotesis!J28 -> 0.2 | J22: =Hipotesis!K28 -> 0.2
B23: Revenue ($M) | D23: =D19*D22 -> 13745 | E23: =E19*E22 -> 17248 | F23: =F19*F22 -> 21616.546 | G23: =G19*G22 -> 25899.947 | H23: =H19*H22 -> 29824.182 | I23: =I19*I22 -> 33104.842 | J23: =J19*J22 -> 36084.277
B25: Op Margin (% revenue) | D25: 0.183 | E25: 0.207 | F25: =Hipotesis!G29 -> 0.19 | G25: =Hipotesis!H29 -> 0.205 | H25: =Hipotesis!I29 -> 0.215 | I25: =Hipotesis!J29 -> 0.22 | J25: =Hipotesis!K29 -> 0.225
B26: Segment Op Income ($M) | D26: =D23*D25 -> 2515.335 | E26: =E23*E25 -> 3570.336 | F26: =F23*F25 -> 4107.1437 | G26: =G23*G25 -> 5309.4892 | H26: =H23*H25 -> 6412.1991 | I26: =I23*I25 -> 7283.0652 | J26: =J23*J25 -> 8118.9624
A28: C. FREIGHT (modelar conservador)
B29: Gross Bookings ($M) | D29: =Historico!H40 -> 5277 | E29: =Historico!I40 -> 5141 | F29: =E29*(1+Hipotesis!G32) -> 5398.05 | G29: =F29*(1+Hipotesis!H32) -> 5667.9525 | H29: =G29*(1+Hipotesis!I32) -> 5894.6706 | I29: =H29*(1+Hipotesis!J32) -> 6071.5107 | J29: =I29*(1+Hipotesis!K32) -> 6253.656
B31: Take Rate (~100%) | D31: =1 -> 1 | E31: =1 -> 1 | F31: =Hipotesis!G33 -> 1 | G31: =Hipotesis!H33 -> 1 | H31: =Hipotesis!I33 -> 1 | I31: =Hipotesis!J33 -> 1 | J31: =Hipotesis!K33 -> 1
B32: Revenue ($M) | D32: =D29*D31 -> 5277 | E32: =E29*E31 -> 5141 | F32: =F29*F31 -> 5398.05 | G32: =G29*G31 -> 5667.9525 | H32: =H29*H31 -> 5894.6706 | I32: =I29*I31 -> 6071.5107 | J32: =J29*J31 -> 6253.656
B34: Op Margin (% revenue) | D34: -0.021 | E34: -0.006 | F34: =Hipotesis!G34 -> -0.015 | G34: =Hipotesis!H34 -> 0 | H34: =Hipotesis!I34 -> 0.005 | I34: =Hipotesis!J34 -> 0.01 | J34: =Hipotesis!K34 -> 0.015
B35: Segment Op Income ($M) | D35: =D32*D34 -> -110.817 | E35: =E32*E34 -> -30.846 | F35: =F32*F34 -> -80.97075 | G35: =G32*G34 -> 0 | H35: =H32*H34 -> 29.473353 | I35: =I32*I34 -> 60.715107 | J35: =J32*J34 -> 93.804841
A37: D. CORPORATE OVERHEAD (driver de overhead dilution) | L37: Sens D. Overhead (% GB) × WACC (precio implicito $)
B38: Total Gross Bookings ($M) | D38: =D7+D19+D29 -> 162184 | E38: =E7+E19+E29 -> 193502 | F38: =F7+F19+F29 -> 233248.53 | G38: =G7+G19+G29 -> 272191.59 | H38: =H7+H19+H29 -> 308374.46 | I38: =I7+I19+I29 -> 341824.08 | J38: =J7+J19+J29 -> 372223.95 | L38: Overhead ↓ WACC →
B39: Corporate cost (% GB) | D39: 0.0207 | E39: 0.0206 | F39: =Hipotesis!G37 -> 0.02 | G39: =Hipotesis!H37 -> 0.018 | H39: =Hipotesis!I37 -> 0.016 | I39: =Hipotesis!J37 -> 0.015 | J39: =Hipotesis!K37 -> 0.014 | M39: 0.085 | N39: 0.092 | O39: 0.098 | P39: 0.105 | Q39: 0.112 | R39: 0.118
B40: Corporate cost ($M) | D40: =-D38*D39 -> -3357.2088 | E40: =-E38*E39 -> -3986.1412 | F40: =-F38*F39 -> -4664.9706 | G40: =-G38*G39 -> -4899.4486 | H40: =-H38*H39 -> -4933.9914 | I40: =-I38*I39 -> -5127.3612 | J40: =-J38*J39 -> -5211.1353 | L40: 0.005 | M40: =(($F$75/(1+M$39)^1+$G$75/(1+M$39)^2+$H$75/(1+M$39)^3+$I$75/(1+M$39)^4+((($J$62+(-$J$40-($L40*$J$38)))*(1-Hipotesis!$D$10))-(($J$67-$I$67)/Hipotesis!$D$40))/(1+M$39)^5)+((((($J$62+(-$J$40-($L40*$J$38)))*(1-Hipotesis!$D$10))-(($J$67-$I$67)/Hipotesis!$D$40))*(1+Hipotesis!$D$15)/(M$39-Hipotesis!$D$15))/(1+M$39)^5)+(Hipotesis!$D$49+Hipotesis!$D$50-Hipotesis!$D$51+Hipotesis!$D$52+Hipotesis!$D$53-Hipotesis!$D$54))/Hipotesis!$D$46*1000 -> 113.73861 | N40: =(($F$75/(1+N$39)^1+$G$75/(1+N$39)^2+$H$75/(1+N$39)^3+$I$75/(1+N$39)^4+((($J$62+(-$J$40-($L40*$J$38)))*(1-Hipotesis!$D$10))-(($J$67-$I$67)/Hipotesis!$D$40))/(1+N$39)^5)+((((($J$62+(-$J$40-($L40*$J$38)))*(1-Hipotesis!$D$10))-(($J$67-$I$67)/Hipotesis!$D$40))*(1+Hipotesis!$D$15)/(N$39-Hipotesis!$D$15))/(1+N$39)^5)+(Hipotesis!$D$49+Hipotesis!$D$50-Hipotesis!$D$51+Hipotesis!$D$52+Hipotesis!$D$53-Hipotesis!$D$54))/Hipotesis!$D$46*1000 -> 100.91974 | O40: =(($F$75/(1+O$39)^1+$G$75/(1+O$39)^2+$H$75/(1+O$39)^3+$I$75/(1+O$39)^4+((($J$62+(-$J$40-($L40*$J$38)))*(1-Hipotesis!$D$10))-(($J$67-$I$67)/Hipotesis!$D$40))/(1+O$39)^5)+((((($J$62+(-$J$40-($L40*$J$38)))*(1-Hipotesis!$D$10))-(($J$67-$I$67)/Hipotesis!$D$40))*(1+Hipotesis!$D$15)/(O$39-Hipotesis!$D$15))/(1+O$39)^5)+(Hipotesis!$D$49+Hipotesis!$D$50-Hipotesis!$D$51+Hipotesis!$D$52+Hipotesis!$D$53-Hipotesis!$D$54))/Hipotesis!$D$46*1000 -> 91.910078 | P40: =(($F$75/(1+P$39)^1+$G$75/(1+P$39)^2+$H$75/(1+P$39)^3+$I$75/(1+P$39)^4+((($J$62+(-$J$40-($L40*$J$38)))*(1-Hipotesis!$D$10))-(($J$67-$I$67)/Hipotesis!$D$40))/(1+P$39)^5)+((((($J$62+(-$J$40-($L40*$J$38)))*(1-Hipotesis!$D$10))-(($J$67-$I$67)/Hipotesis!$D$40))*(1+Hipotesis!$D$15)/(P$39-Hipotesis!$D$15))/(1+P$39)^5)+(Hipotesis!$D$49+Hipotesis!$D$50-Hipotesis!$D$51+Hipotesis!$D$52+Hipotesis!$D$53-Hipotesis!$D$54))/Hipotesis!$D$46*1000 -> 83.128776 | Q40: =(($F$75/(1+Q$39)^1+$G$75/(1+Q$39)^2+$H$75/(1+Q$39)^3+$I$75/(1+Q$39)^4+((($J$62+(-$J$40-($L40*$J$38)))*(1-Hipotesis!$D$10))-(($J$67-$I$67)/Hipotesis!$D$40))/(1+Q$39)^5)+((((($J$62+(-$J$40-($L40*$J$38)))*(1-Hipotesis!$D$10))-(($J$67-$I$67)/Hipotesis!$D$40))*(1+Hipotesis!$D$15)/(Q$39-Hipotesis!$D$15))/(1+Q$39)^5)+(Hipotesis!$D$49+Hipotesis!$D$50-Hipotesis!$D$51+Hipotesis!$D$52+Hipotesis!$D$53-Hipotesis!$D$54))/Hipotesis!$D$46*1000 -> 75.781525 | R40: =(($F$75/(1+R$39)^1+$G$75/(1+R$39)^2+$H$75/(1+R$39)^3+$I$75/(1+R$39)^4+((($J$62+(-$J$40-($L40*$J$38)))*(1-Hipotesis!$D$10))-(($J$67-$I$67)/Hipotesis!$D$40))/(1+R$39)^5)+((((($J$62+(-$J$40-($L40*$J$38)))*(1-Hipotesis!$D$10))-(($J$67-$I$67)/Hipotesis!$D$40))*(1+Hipotesis!$D$15)/(R$39-Hipotesis!$D$15))/(1+R$39)^5)+(Hipotesis!$D$49+Hipotesis!$D$50-Hipotesis!$D$51+Hipotesis!$D$52+Hipotesis!$D$53-Hipotesis!$D$54))/Hipotesis!$D$46*1000 -> 70.379306
L41: 0.01 | M41: =(($F$75/(1+M$39)^1+$G$75/(1+M$39)^2+$H$75/(1+M$39)^3+$I$75/(1+M$39)^4+((($J$62+(-$J$40-($L41*$J$38)))*(1-Hipotesis!$D$10))-(($J$67-$I$67)/Hipotesis!$D$40))/(1+M$39)^5)+((((($J$62+(-$J$40-($L41*$J$38)))*(1-Hipotesis!$D$10))-(($J$67-$I$67)/Hipotesis!$D$40))*(1+Hipotesis!$D$15)/(M$39-Hipotesis!$D$15))/(1+M$39)^5)+(Hipotesis!$D$49+Hipotesis!$D$50-Hipotesis!$D$51+Hipotesis!$D$52+Hipotesis!$D$53-Hipotesis!$D$54))/Hipotesis!$D$46*1000 -> 105.31037 | N41: =(($F$75/(1+N$39)^1+$G$75/(1+N$39)^2+$H$75/(1+N$39)^3+$I$75/(1+N$39)^4+((($J$62+(-$J$40-($L41*$J$38)))*(1-Hipotesis!$D$10))-(($J$67-$I$67)/Hipotesis!$D$40))/(1+N$39)^5)+((((($J$62+(-$J$40-($L41*$J$38)))*(1-Hipotesis!$D$10))-(($J$67-$I$67)/Hipotesis!$D$40))*(1+Hipotesis!$D$15)/(N$39-Hipotesis!$D$15))/(1+N$39)^5)+(Hipotesis!$D$49+Hipotesis!$D$50-Hipotesis!$D$51+Hipotesis!$D$52+Hipotesis!$D$53-Hipotesis!$D$54))/Hipotesis!$D$46*1000 -> 93.563739 | O41: =(($F$75/(1+O$39)^1+$G$75/(1+O$39)^2+$H$75/(1+O$39)^3+$I$75/(1+O$39)^4+((($J$62+(-$J$40-($L41*$J$38)))*(1-Hipotesis!$D$10))-(($J$67-$I$67)/Hipotesis!$D$40))/(1+O$39)^5)+((((($J$62+(-$J$40-($L41*$J$38)))*(1-Hipotesis!$D$10))-(($J$67-$I$67)/Hipotesis!$D$40))*(1+Hipotesis!$D$15)/(O$39-Hipotesis!$D$15))/(1+O$39)^5)+(Hipotesis!$D$49+Hipotesis!$D$50-Hipotesis!$D$51+Hipotesis!$D$52+Hipotesis!$D$53-Hipotesis!$D$54))/Hipotesis!$D$46*1000 -> 85.305051 | P41: =(($F$75/(1+P$39)^1+$G$75/(1+P$39)^2+$H$75/(1+P$39)^3+$I$75/(1+P$39)^4+((($J$62+(-$J$40-($L41*$J$38)))*(1-Hipotesis!$D$10))-(($J$67-$I$67)/Hipotesis!$D$40))/(1+P$39)^5)+((((($J$62+(-$J$40-($L41*$J$38)))*(1-Hipotesis!$D$10))-(($J$67-$I$67)/Hipotesis!$D$40))*(1+Hipotesis!$D$15)/(P$39-Hipotesis!$D$15))/(1+P$39)^5)+(Hipotesis!$D$49+Hipotesis!$D$50-Hipotesis!$D$51+Hipotesis!$D$52+Hipotesis!$D$53-Hipotesis!$D$54))/Hipotesis!$D$46*1000 -> 77.252966 | Q41: =(($F$75/(1+Q$39)^1+$G$75/(1+Q$39)^2+$H$75/(1+Q$39)^3+$I$75/(1+Q$39)^4+((($J$62+(-$J$40-($L41*$J$38)))*(1-Hipotesis!$D$10))-(($J$67-$I$67)/Hipotesis!$D$40))/(1+Q$39)^5)+((((($J$62+(-$J$40-($L41*$J$38)))*(1-Hipotesis!$D$10))-(($J$67-$I$67)/Hipotesis!$D$40))*(1+Hipotesis!$D$15)/(Q$39-Hipotesis!$D$15))/(1+Q$39)^5)+(Hipotesis!$D$49+Hipotesis!$D$50-Hipotesis!$D$51+Hipotesis!$D$52+Hipotesis!$D$53-Hipotesis!$D$54))/Hipotesis!$D$46*1000 -> 70.51325 | R41: =(($F$75/(1+R$39)^1+$G$75/(1+R$39)^2+$H$75/(1+R$39)^3+$I$75/(1+R$39)^4+((($J$62+(-$J$40-($L41*$J$38)))*(1-Hipotesis!$D$10))-(($J$67-$I$67)/Hipotesis!$D$40))/(1+R$39)^5)+((((($J$62+(-$J$40-($L41*$J$38)))*(1-Hipotesis!$D$10))-(($J$67-$I$67)/Hipotesis!$D$40))*(1+Hipotesis!$D$15)/(R$39-Hipotesis!$D$15))/(1+R$39)^5)+(Hipotesis!$D$49+Hipotesis!$D$50-Hipotesis!$D$51+Hipotesis!$D$52+Hipotesis!$D$53-Hipotesis!$D$54))/Hipotesis!$D$46*1000 -> 65.555868
L42: 0.014 | M42: =(($F$75/(1+M$39)^1+$G$75/(1+M$39)^2+$H$75/(1+M$39)^3+$I$75/(1+M$39)^4+((($J$62+(-$J$40-($L42*$J$38)))*(1-Hipotesis!$D$10))-(($J$67-$I$67)/Hipotesis!$D$40))/(1+M$39)^5)+((((($J$62+(-$J$40-($L42*$J$38)))*(1-Hipotesis!$D$10))-(($J$67-$I$67)/Hipotesis!$D$40))*(1+Hipotesis!$D$15)/(M$39-Hipotesis!$D$15))/(1+M$39)^5)+(Hipotesis!$D$49+Hipotesis!$D$50-Hipotesis!$D$51+Hipotesis!$D$52+Hipotesis!$D$53-Hipotesis!$D$54))/Hipotesis!$D$46*1000 -> 98.567786 | N42: =(($F$75/(1+N$39)^1+$G$75/(1+N$39)^2+$H$75/(1+N$39)^3+$I$75/(1+N$39)^4+((($J$62+(-$J$40-($L42*$J$38)))*(1-Hipotesis!$D$10))-(($J$67-$I$67)/Hipotesis!$D$40))/(1+N$39)^5)+((((($J$62+(-$J$40-($L42*$J$38)))*(1-Hipotesis!$D$10))-(($J$67-$I$67)/Hipotesis!$D$40))*(1+Hipotesis!$D$15)/(N$39-Hipotesis!$D$15))/(1+N$39)^5)+(Hipotesis!$D$49+Hipotesis!$D$50-Hipotesis!$D$51+Hipotesis!$D$52+Hipotesis!$D$53-Hipotesis!$D$54))/Hipotesis!$D$46*1000 -> 87.678943 | O42: =(($F$75/(1+O$39)^1+$G$75/(1+O$39)^2+$H$75/(1+O$39)^3+$I$75/(1+O$39)^4+((($J$62+(-$J$40-($L42*$J$38)))*(1-Hipotesis!$D$10))-(($J$67-$I$67)/Hipotesis!$D$40))/(1+O$39)^5)+((((($J$62+(-$J$40-($L42*$J$38)))*(1-Hipotesis!$D$10))-(($J$67-$I$67)/Hipotesis!$D$40))*(1+Hipotesis!$D$15)/(O$39-Hipotesis!$D$15))/(1+O$39)^5)+(Hipotesis!$D$49+Hipotesis!$D$50-Hipotesis!$D$51+Hipotesis!$D$52+Hipotesis!$D$53-Hipotesis!$D$54))/Hipotesis!$D$46*1000 -> 80.021029 | P42: =(($F$75/(1+P$39)^1+$G$75/(1+P$39)^2+$H$75/(1+P$39)^3+$I$75/(1+P$39)^4+((($J$62+(-$J$40-($L42*$J$38)))*(1-Hipotesis!$D$10))-(($J$67-$I$67)/Hipotesis!$D$40))/(1+P$39)^5)+((((($J$62+(-$J$40-($L42*$J$38)))*(1-Hipotesis!$D$10))-(($J$67-$I$67)/Hipotesis!$D$40))*(1+Hipotesis!$D$15)/(P$39-Hipotesis!$D$15))/(1+P$39)^5)+(Hipotesis!$D$49+Hipotesis!$D$50-Hipotesis!$D$51+Hipotesis!$D$52+Hipotesis!$D$53-Hipotesis!$D$54))/Hipotesis!$D$46*1000 -> 72.552318 | Q42: =(($F$75/(1+Q$39)^1+$G$75/(1+Q$39)^2+$H$75/(1+Q$39)^3+$I$75/(1+Q$39)^4+((($J$62+(-$J$40-($L42*$J$38)))*(1-Hipotesis!$D$10))-(($J$67-$I$67)/Hipotesis!$D$40))/(1+Q$39)^5)+((((($J$62+(-$J$40-($L42*$J$38)))*(1-Hipotesis!$D$10))-(($J$67-$I$67)/Hipotesis!$D$40))*(1+Hipotesis!$D$15)/(Q$39-Hipotesis!$D$15))/(1+Q$39)^5)+(Hipotesis!$D$49+Hipotesis!$D$50-Hipotesis!$D$51+Hipotesis!$D$52+Hipotesis!$D$53-Hipotesis!$D$54))/Hipotesis!$D$46*1000 -> 66.29863 | R42: =(($F$75/(1+R$39)^1+$G$75/(1+R$39)^2+$H$75/(1+R$39)^3+$I$75/(1+R$39)^4+((($J$62+(-$J$40-($L42*$J$38)))*(1-Hipotesis!$D$10))-(($J$67-$I$67)/Hipotesis!$D$40))/(1+R$39)^5)+((((($J$62+(-$J$40-($L42*$J$38)))*(1-Hipotesis!$D$10))-(($J$67-$I$67)/Hipotesis!$D$40))*(1+Hipotesis!$D$15)/(R$39-Hipotesis!$D$15))/(1+R$39)^5)+(Hipotesis!$D$49+Hipotesis!$D$50-Hipotesis!$D$51+Hipotesis!$D$52+Hipotesis!$D$53-Hipotesis!$D$54))/Hipotesis!$D$46*1000 -> 61.697118
L43: 0.018 | M43: =(($F$75/(1+M$39)^1+$G$75/(1+M$39)^2+$H$75/(1+M$39)^3+$I$75/(1+M$39)^4+((($J$62+(-$J$40-($L43*$J$38)))*(1-Hipotesis!$D$10))-(($J$67-$I$67)/Hipotesis!$D$40))/(1+M$39)^5)+((((($J$62+(-$J$40-($L43*$J$38)))*(1-Hipotesis!$D$10))-(($J$67-$I$67)/Hipotesis!$D$40))*(1+Hipotesis!$D$15)/(M$39-Hipotesis!$D$15))/(1+M$39)^5)+(Hipotesis!$D$49+Hipotesis!$D$50-Hipotesis!$D$51+Hipotesis!$D$52+Hipotesis!$D$53-Hipotesis!$D$54))/Hipotesis!$D$46*1000 -> 91.825198 | N43: =(($F$75/(1+N$39)^1+$G$75/(1+N$39)^2+$H$75/(1+N$39)^3+$I$75/(1+N$39)^4+((($J$62+(-$J$40-($L43*$J$38)))*(1-Hipotesis!$D$10))-(($J$67-$I$67)/Hipotesis!$D$40))/(1+N$39)^5)+((((($J$62+(-$J$40-($L43*$J$38)))*(1-Hipotesis!$D$10))-(($J$67-$I$67)/Hipotesis!$D$40))*(1+Hipotesis!$D$15)/(N$39-Hipotesis!$D$15))/(1+N$39)^5)+(Hipotesis!$D$49+Hipotesis!$D$50-Hipotesis!$D$51+Hipotesis!$D$52+Hipotesis!$D$53-Hipotesis!$D$54))/Hipotesis!$D$46*1000 -> 81.794146 | O43: =(($F$75/(1+O$39)^1+$G$75/(1+O$39)^2+$H$75/(1+O$39)^3+$I$75/(1+O$39)^4+((($J$62+(-$J$40-($L43*$J$38)))*(1-Hipotesis!$D$10))-(($J$67-$I$67)/Hipotesis!$D$40))/(1+O$39)^5)+((((($J$62+(-$J$40-($L43*$J$38)))*(1-Hipotesis!$D$10))-(($J$67-$I$67)/Hipotesis!$D$40))*(1+Hipotesis!$D$15)/(O$39-Hipotesis!$D$15))/(1+O$39)^5)+(Hipotesis!$D$49+Hipotesis!$D$50-Hipotesis!$D$51+Hipotesis!$D$52+Hipotesis!$D$53-Hipotesis!$D$54))/Hipotesis!$D$46*1000 -> 74.737007 | P43: =(($F$75/(1+P$39)^1+$G$75/(1+P$39)^2+$H$75/(1+P$39)^3+$I$75/(1+P$39)^4+((($J$62+(-$J$40-($L43*$J$38)))*(1-Hipotesis!$D$10))-(($J$67-$I$67)/Hipotesis!$D$40))/(1+P$39)^5)+((((($J$62+(-$J$40-($L43*$J$38)))*(1-Hipotesis!$D$10))-(($J$67-$I$67)/Hipotesis!$D$40))*(1+Hipotesis!$D$15)/(P$39-Hipotesis!$D$15))/(1+P$39)^5)+(Hipotesis!$D$49+Hipotesis!$D$50-Hipotesis!$D$51+Hipotesis!$D$52+Hipotesis!$D$53-Hipotesis!$D$54))/Hipotesis!$D$46*1000 -> 67.85167 | Q43: =(($F$75/(1+Q$39)^1+$G$75/(1+Q$39)^2+$H$75/(1+Q$39)^3+$I$75/(1+Q$39)^4+((($J$62+(-$J$40-($L43*$J$38)))*(1-Hipotesis!$D$10))-(($J$67-$I$67)/Hipotesis!$D$40))/(1+Q$39)^5)+((((($J$62+(-$J$40-($L43*$J$38)))*(1-Hipotesis!$D$10))-(($J$67-$I$67)/Hipotesis!$D$40))*(1+Hipotesis!$D$15)/(Q$39-Hipotesis!$D$15))/(1+Q$39)^5)+(Hipotesis!$D$49+Hipotesis!$D$50-Hipotesis!$D$51+Hipotesis!$D$52+Hipotesis!$D$53-Hipotesis!$D$54))/Hipotesis!$D$46*1000 -> 62.08401 | R43: =(($F$75/(1+R$39)^1+$G$75/(1+R$39)^2+$H$75/(1+R$39)^3+$I$75/(1+R$39)^4+((($J$62+(-$J$40-($L43*$J$38)))*(1-Hipotesis!$D$10))-(($J$67-$I$67)/Hipotesis!$D$40))/(1+R$39)^5)+((((($J$62+(-$J$40-($L43*$J$38)))*(1-Hipotesis!$D$10))-(($J$67-$I$67)/Hipotesis!$D$40))*(1+Hipotesis!$D$15)/(R$39-Hipotesis!$D$15))/(1+R$39)^5)+(Hipotesis!$D$49+Hipotesis!$D$50-Hipotesis!$D$51+Hipotesis!$D$52+Hipotesis!$D$53-Hipotesis!$D$54))/Hipotesis!$D$46*1000 -> 57.838368
L44: 0.022 | M44: =(($F$75/(1+M$39)^1+$G$75/(1+M$39)^2+$H$75/(1+M$39)^3+$I$75/(1+M$39)^4+((($J$62+(-$J$40-($L44*$J$38)))*(1-Hipotesis!$D$10))-(($J$67-$I$67)/Hipotesis!$D$40))/(1+M$39)^5)+((((($J$62+(-$J$40-($L44*$J$38)))*(1-Hipotesis!$D$10))-(($J$67-$I$67)/Hipotesis!$D$40))*(1+Hipotesis!$D$15)/(M$39-Hipotesis!$D$15))/(1+M$39)^5)+(Hipotesis!$D$49+Hipotesis!$D$50-Hipotesis!$D$51+Hipotesis!$D$52+Hipotesis!$D$53-Hipotesis!$D$54))/Hipotesis!$D$46*1000 -> 85.08261 | N44: =(($F$75/(1+N$39)^1+$G$75/(1+N$39)^2+$H$75/(1+N$39)^3+$I$75/(1+N$39)^4+((($J$62+(-$J$40-($L44*$J$38)))*(1-Hipotesis!$D$10))-(($J$67-$I$67)/Hipotesis!$D$40))/(1+N$39)^5)+((((($J$62+(-$J$40-($L44*$J$38)))*(1-Hipotesis!$D$10))-(($J$67-$I$67)/Hipotesis!$D$40))*(1+Hipotesis!$D$15)/(N$39-Hipotesis!$D$15))/(1+N$39)^5)+(Hipotesis!$D$49+Hipotesis!$D$50-Hipotesis!$D$51+Hipotesis!$D$52+Hipotesis!$D$53-Hipotesis!$D$54))/Hipotesis!$D$46*1000 -> 75.909349 | O44: =(($F$75/(1+O$39)^1+$G$75/(1+O$39)^2+$H$75/(1+O$39)^3+$I$75/(1+O$39)^4+((($J$62+(-$J$40-($L44*$J$38)))*(1-Hipotesis!$D$10))-(($J$67-$I$67)/Hipotesis!$D$40))/(1+O$39)^5)+((((($J$62+(-$J$40-($L44*$J$38)))*(1-Hipotesis!$D$10))-(($J$67-$I$67)/Hipotesis!$D$40))*(1+Hipotesis!$D$15)/(O$39-Hipotesis!$D$15))/(1+O$39)^5)+(Hipotesis!$D$49+Hipotesis!$D$50-Hipotesis!$D$51+Hipotesis!$D$52+Hipotesis!$D$53-Hipotesis!$D$54))/Hipotesis!$D$46*1000 -> 69.452985 | P44: =(($F$75/(1+P$39)^1+$G$75/(1+P$39)^2+$H$75/(1+P$39)^3+$I$75/(1+P$39)^4+((($J$62+(-$J$40-($L44*$J$38)))*(1-Hipotesis!$D$10))-(($J$67-$I$67)/Hipotesis!$D$40))/(1+P$39)^5)+((((($J$62+(-$J$40-($L44*$J$38)))*(1-Hipotesis!$D$10))-(($J$67-$I$67)/Hipotesis!$D$40))*(1+Hipotesis!$D$15)/(P$39-Hipotesis!$D$15))/(1+P$39)^5)+(Hipotesis!$D$49+Hipotesis!$D$50-Hipotesis!$D$51+Hipotesis!$D$52+Hipotesis!$D$53-Hipotesis!$D$54))/Hipotesis!$D$46*1000 -> 63.151022 | Q44: =(($F$75/(1+Q$39)^1+$G$75/(1+Q$39)^2+$H$75/(1+Q$39)^3+$I$75/(1+Q$39)^4+((($J$62+(-$J$40-($L44*$J$38)))*(1-Hipotesis!$D$10))-(($J$67-$I$67)/Hipotesis!$D$40))/(1+Q$39)^5)+((((($J$62+(-$J$40-($L44*$J$38)))*(1-Hipotesis!$D$10))-(($J$67-$I$67)/Hipotesis!$D$40))*(1+Hipotesis!$D$15)/(Q$39-Hipotesis!$D$15))/(1+Q$39)^5)+(Hipotesis!$D$49+Hipotesis!$D$50-Hipotesis!$D$51+Hipotesis!$D$52+Hipotesis!$D$53-Hipotesis!$D$54))/Hipotesis!$D$46*1000 -> 57.86939 | R44: =(($F$75/(1+R$39)^1+$G$75/(1+R$39)^2+$H$75/(1+R$39)^3+$I$75/(1+R$39)^4+((($J$62+(-$J$40-($L44*$J$38)))*(1-Hipotesis!$D$10))-(($J$67-$I$67)/Hipotesis!$D$40))/(1+R$39)^5)+((((($J$62+(-$J$40-($L44*$J$38)))*(1-Hipotesis!$D$10))-(($J$67-$I$67)/Hipotesis!$D$40))*(1+Hipotesis!$D$15)/(R$39-Hipotesis!$D$15))/(1+R$39)^5)+(Hipotesis!$D$49+Hipotesis!$D$50-Hipotesis!$D$51+Hipotesis!$D$52+Hipotesis!$D$53-Hipotesis!$D$54))/Hipotesis!$D$46*1000 -> 53.979617
L45: 0.026 | M45: =(($F$75/(1+M$39)^1+$G$75/(1+M$39)^2+$H$75/(1+M$39)^3+$I$75/(1+M$39)^4+((($J$62+(-$J$40-($L45*$J$38)))*(1-Hipotesis!$D$10))-(($J$67-$I$67)/Hipotesis!$D$40))/(1+M$39)^5)+((((($J$62+(-$J$40-($L45*$J$38)))*(1-Hipotesis!$D$10))-(($J$67-$I$67)/Hipotesis!$D$40))*(1+Hipotesis!$D$15)/(M$39-Hipotesis!$D$15))/(1+M$39)^5)+(Hipotesis!$D$49+Hipotesis!$D$50-Hipotesis!$D$51+Hipotesis!$D$52+Hipotesis!$D$53-Hipotesis!$D$54))/Hipotesis!$D$46*1000 -> 78.340022 | N45: =(($F$75/(1+N$39)^1+$G$75/(1+N$39)^2+$H$75/(1+N$39)^3+$I$75/(1+N$39)^4+((($J$62+(-$J$40-($L45*$J$38)))*(1-Hipotesis!$D$10))-(($J$67-$I$67)/Hipotesis!$D$40))/(1+N$39)^5)+((((($J$62+(-$J$40-($L45*$J$38)))*(1-Hipotesis!$D$10))-(($J$67-$I$67)/Hipotesis!$D$40))*(1+Hipotesis!$D$15)/(N$39-Hipotesis!$D$15))/(1+N$39)^5)+(Hipotesis!$D$49+Hipotesis!$D$50-Hipotesis!$D$51+Hipotesis!$D$52+Hipotesis!$D$53-Hipotesis!$D$54))/Hipotesis!$D$46*1000 -> 70.024552 | O45: =(($F$75/(1+O$39)^1+$G$75/(1+O$39)^2+$H$75/(1+O$39)^3+$I$75/(1+O$39)^4+((($J$62+(-$J$40-($L45*$J$38)))*(1-Hipotesis!$D$10))-(($J$67-$I$67)/Hipotesis!$D$40))/(1+O$39)^5)+((((($J$62+(-$J$40-($L45*$J$38)))*(1-Hipotesis!$D$10))-(($J$67-$I$67)/Hipotesis!$D$40))*(1+Hipotesis!$D$15)/(O$39-Hipotesis!$D$15))/(1+O$39)^5)+(Hipotesis!$D$49+Hipotesis!$D$50-Hipotesis!$D$51+Hipotesis!$D$52+Hipotesis!$D$53-Hipotesis!$D$54))/Hipotesis!$D$46*1000 -> 64.168963 | P45: =(($F$75/(1+P$39)^1+$G$75/(1+P$39)^2+$H$75/(1+P$39)^3+$I$75/(1+P$39)^4+((($J$62+(-$J$40-($L45*$J$38)))*(1-Hipotesis!$D$10))-(($J$67-$I$67)/Hipotesis!$D$40))/(1+P$39)^5)+((((($J$62+(-$J$40-($L45*$J$38)))*(1-Hipotesis!$D$10))-(($J$67-$I$67)/Hipotesis!$D$40))*(1+Hipotesis!$D$15)/(P$39-Hipotesis!$D$15))/(1+P$39)^5)+(Hipotesis!$D$49+Hipotesis!$D$50-Hipotesis!$D$51+Hipotesis!$D$52+Hipotesis!$D$53-Hipotesis!$D$54))/Hipotesis!$D$46*1000 -> 58.450374 | Q45: =(($F$75/(1+Q$39)^1+$G$75/(1+Q$39)^2+$H$75/(1+Q$39)^3+$I$75/(1+Q$39)^4+((($J$62+(-$J$40-($L45*$J$38)))*(1-Hipotesis!$D$10))-(($J$67-$I$67)/Hipotesis!$D$40))/(1+Q$39)^5)+((((($J$62+(-$J$40-($L45*$J$38)))*(1-Hipotesis!$D$10))-(($J$67-$I$67)/Hipotesis!$D$40))*(1+Hipotesis!$D$15)/(Q$39-Hipotesis!$D$15))/(1+Q$39)^5)+(Hipotesis!$D$49+Hipotesis!$D$50-Hipotesis!$D$51+Hipotesis!$D$52+Hipotesis!$D$53-Hipotesis!$D$54))/Hipotesis!$D$46*1000 -> 53.65477 | R45: =(($F$75/(1+R$39)^1+$G$75/(1+R$39)^2+$H$75/(1+R$39)^3+$I$75/(1+R$39)^4+((($J$62+(-$J$40-($L45*$J$38)))*(1-Hipotesis!$D$10))-(($J$67-$I$67)/Hipotesis!$D$40))/(1+R$39)^5)+((((($J$62+(-$J$40-($L45*$J$38)))*(1-Hipotesis!$D$10))-(($J$67-$I$67)/Hipotesis!$D$40))*(1+Hipotesis!$D$15)/(R$39-Hipotesis!$D$15))/(1+R$39)^5)+(Hipotesis!$D$49+Hipotesis!$D$50-Hipotesis!$D$51+Hipotesis!$D$52+Hipotesis!$D$53-Hipotesis!$D$54))/Hipotesis!$D$46*1000 -> 50.120867
L47: Q1 2026: 2.0%. Tesis pide bajar a ~1.4% para 2030. Cada 50bps mueve precio notablemente.
A49: E. CONSOLIDADO - EBIT y EBITDA
B50: Mobility Op Income | D50: =D15 -> 5819.952 | E50: =E15 -> 7150.47 | F50: =F15 -> 9125.7192 | G50: =G15 -> 11542.631 | H50: =H15 -> 13706.45 | I50: =I15 -> 15729.1 | J50: =J15 -> 17404.488
...

Sheet DuPont_WC
A1: DuPont ROE + WORKING CAPITAL ANALYSIS
B2: LEYENDA: | C2: AZUL+AMARILLO | D2: Input hardcoded (editable) | E2: AMARILLO FUERTE | F2: Input clave (driver de sensibilidad) | G2: NEGRO | H2: Formula (calculado) | I2: VERDE | J2: Link a otra hoja | K2: VERDE CLARO | L2: Resultado / output
D4: 2020A | E4: 2021A | F4: 2022A | G4: 2023A | H4: 2024A | I4: 2025A
A6: 1. DuPont 5-STEP DECOMPOSITION (datos historicos)
B7: ROE = Tax × Interest × Op Margin × Asset Turnover × Leverage
A9: Inputs (links Historico)
B10: Revenue | D10: =Historico!D7 -> 11139 | E10: =Historico!E7 -> 17455 | F10: =Historico!F7 -> 31877 | G10: =Historico!G7 -> 37281 | H10: =Historico!H7 -> 43978 | I10: =Historico!I7 -> 52017
B11: EBIT (GAAP Operating Income) | D11: =Historico!D17 -> -4863 | E11: =Historico!E17 -> -3824 | F11: =Historico!F17 -> -1832 | G11: =Historico!G17 -> 1110 | H11: =Historico!H17 -> 2799 | I11: =Historico!I17 -> 5565
B12: Non-operating income/(loss) - hardcode | D12: -2725 | E12: 3292 | F12: -7029 | G12: 738 | H12: 7350 | I12: 4500
B13: EBT = EBIT + Non-op | D13: =D11+D12 -> -7588 | E13: =E11+E12 -> -532 | F13: =F11+F12 -> -8861 | G13: =G11+G12 -> 1848 | H13: =H11+H12 -> 10149 | I13: =I11+I12 -> 10065
B14: Net Income (UBER) | D14: =Historico!D22 -> -6768 | E14: =Historico!E22 -> -496 | F14: =Historico!F22 -> -9141 | G14: =Historico!G22 -> 1887 | H14: =Historico!H22 -> 9856 | I14: =Historico!I22 -> 10053
B15: Total Assets (avg of beg+end) | D15: =Historico!D49 -> 33252 | E15: =(Historico!D49+Historico!E49)/2 -> 36013 | F15: =(Historico!E49+Historico!F49)/2 -> 35441.5 | G15: =(Historico!F49+Historico!G49)/2 -> 35404 | H15: =(Historico!G49+Historico!H49)/2 -> 44971.5 | I15: =(Historico!H49+Historico!I49)/2 -> 56523
B16: Stockholders' Equity (avg) | D16: =Historico!D50 -> 12266 | E16: =(Historico!D50+Historico!E50)/2 -> 13362 | F16: =(Historico!E50+Historico!F50)/2 -> 10899 | G16: =(Historico!F50+Historico!G50)/2 -> 9294.5 | H16: =(Historico!G50+Historico!H50)/2 -> 16403.5 | I16: =(Historico!H50+Historico!I50)/2 -> 24299.5
A18: Componentes de DuPont 5-step
B19: Tax Burden (NI / EBT) | D19: =IFERROR(D14/D13,0) -> 0.89193463 | E19: =IFERROR(E14/E13,0) -> 0.93233083 | F19: =IFERROR(F14/F13,0) -> 1.0315991 | G19: =IFERROR(G14/G13,0) -> 1.0211039 | H19: =IFERROR(H14/H13,0) -> 0.97113016 | I19: =IFERROR(I14/I13,0) -> 0.99880775
B20: Interest Burden (EBT / EBIT) | D20: =IFERROR(D13/D11,0) -> 1.5603537 | E20: =IFERROR(E13/E11,0) -> 0.13912134 | F20: =IFERROR(F13/F11,0) -> 4.8367904 | G20: =IFERROR(G13/G11,0) -> 1.6648649 | H20: =IFERROR(H13/H11,0) -> 3.6259378 | I20: =IFERROR(I13/I11,0) -> 1.8086253
B21: EBIT margin (EBIT / Revenue) | D21: =D11/D10 -> -0.4365742 | E21: =E11/E10 -> -0.21907763 | F21: =F11/F10 -> -0.057470904 | G21: =G11/G10 -> 0.029773879 | H21: =H11/H10 -> 0.063645459 | I21: =I11/I10 -> 0.10698426
B22: Asset Turnover (Revenue / Assets) | D22: =D10/D15 -> 0.33498737 | E22: =E10/E15 -> 0.48468609 | F22: =F10/F15 -> 0.89942581 | G22: =G10/G15 -> 1.0530166 | H22: =H10/H15 -> 0.97790823 | I22: =I10/I15 -> 0.92028024
B23: Equity Multiplier (Assets / Equity) | D23: =D15/D16 -> 2.7109082 | E23: =E15/E16 -> 2.6951804 | F23: =F15/F16 -> 3.2518121 | G23: =G15/G16 -> 3.8091344 | H23: =H15/H16 -> 2.7415795 | I23: =I15/I16 -> 2.3260972
B25: ROE (5-step product) | D25: =D19*D20*D21*D22*D23 -> -0.55176912 | E25: =E19*E20*E21*E22*E23 -> -0.037120192 | F25: =F19*F20*F21*F22*F23 -> -0.8387008 | G25: =G19*G20*G21*G22*G23 -> 0.20302329 | H25: =H19*H20*H21*H22*H23 -> 0.60084738 | I25: =I19*I20*I21*I22*I23 -> 0.41371222
B26: ROE (NI / Equity, check) | D26: =D14/D16 -> -0.55176912 | E26: =E14/E16 -> -0.037120192 | F26: =F14/F16 -> -0.8387008 | G26: =G14/G16 -> 0.20302329 | H26: =H14/H16 -> 0.60084738 | I26: =I14/I16 -> 0.41371222
B28: Comentario: | D28: ROE 2024-2025 distorsionado por valuation allowance release y ganancias en equity stakes.
A30: 2. ROE OPERATIVO (NOPAT-based, mas representativo)
B31: Limpia distorsiones de tax NOLs y equity investment marks
B33: EBIT (de arriba) | D33: =D11 -> -4863 | E33: =E11 -> -3824 | F33: =F11 -> -1832 | G33: =G11 -> 1110 | H33: =H11 -> 2799 | I33: =I11 -> 5565
B34: Tipo impositivo asumido (Hipotesis) | D34: =Hipotesis!$D$10 -> 0.22 | E34: =Hipotesis!$D$10 -> 0.22 | F34: =Hipotesis!$D$10 -> 0.22 | G34: =Hipotesis!$D$10 -> 0.22 | H34: =Hipotesis!$D$10 -> 0.22 | I34: =Hipotesis!$D$10 -> 0.22
B35: NOPAT = EBIT × (1-T) | D35: =D33*(1-D34) -> -3793.14 | E35: =E33*(1-E34) -> -2982.72 | F35: =F33*(1-F34) -> -1428.96 | G35: =G33*(1-G34) -> 865.8 | H35: =H33*(1-H34) -> 2183.22 | I35: =I33*(1-I34) -> 4340.7
B36: Capital invertido (Equity + LT debt - Cash) | D36: =Historico!D50+Historico!D52-Historico!D53 -> 12435 | E36: =Historico!E50+Historico!E52-Historico!E53 -> 15929 | F36: =Historico!F50+Historico!F52-Historico!F53 -> 11198 | G36: =Historico!G50+Historico!G52-Historico!G53 -> 15481 | H36: =Historico!H50+Historico!H52-Historico!H53 -> 25100 | I36: =Historico!I50+Historico!I52-Historico!I53 -> 29929
B37: ROIC operativo = NOPAT / Capital invertido | D37: =IFERROR(D35/D36,0) -> -0.30503739 | E37: =IFERROR(E35/E36,0) -> -0.18725093 | F37: =IFERROR(F35/F36,0) -> -0.1276085 | G37: =IFERROR(G35/G36,0) -> 0.05592662 | H37: =IFERROR(H35/H36,0) -> 0.086980876 | I37: =IFERROR(I35/I36,0) -> 0.14503325
B38: ROCE = EBIT / Capital invertido | D38: =IFERROR(D33/D36,0) -> -0.39107358 | E38: =IFERROR(E33/E36,0) -> -0.24006529 | F38: =IFERROR(F33/F36,0) -> -0.16360064 | G38: =IFERROR(G33/G36,0) -> 0.071700795 | H38: =IFERROR(H33/H36,0) -> 0.11151394 | I38: =IFERROR(I33/I36,0) -> 0.18594006
B40: Lectura:
B41: - ROE GAAP 2025 = ~37% pero distorsionado al alza
B42: - ROIC operativo subyacente = ~25-30% (FY2025) — un negocio con muy alto retorno sobre capital
B43: - La trayectoria 2020 → 2025 muestra el flip de quema de capital a generacion de valor
A46: 3. WORKING CAPITAL ANALYSIS
A48: Componentes de WC (links Historico)
B49: Accounts Receivable | D49: =Historico!D54 -> 1110 | E49: =Historico!E54 -> 2439 | F49: =Historico!F54 -> 2477 | G49: =Historico!G54 -> 2779 | H49: =Historico!H54 -> 3399 | I49: =Historico!I54 -> 3850
B50: Accounts Payable | D50: =Historico!D55 -> 235 | E50: =Historico!E55 -> 396 | F50: =Historico!F55 -> 622 | G50: =Historico!G55 -> 712 | H50: =Historico!H55 -> 858 | I50: =Historico!I55 -> 1013
B51: ST Insurance reserves | D51: =Historico!D56 -> 1243 | E51: =Historico!E56 -> 1442 | F51: =Historico!F56 -> 2049 | G51: =Historico!G56 -> 2528 | H51: =Historico!H56 -> 2754 | I51: =Historico!I56 -> 3050
B52: LT Insurance reserves | D52: =Historico!D57 -> 2812 | E52: =Historico!E57 -> 2823 | F52: =Historico!F57 -> 3370 | G52: =Historico!G57 -> 3736 | H52: =Historico!H57 -> 4102 | I52: =Historico!I57 -> 4400
...

Sheet Reverse_DCF
A1: REVERSE DCF - que esta priceando el mercado
B2: LEYENDA: | C2: AZUL+AMARILLO | D2: Input hardcoded (editable) | E2: AMARILLO FUERTE | F2: Input clave (driver de sensibilidad) | G2: NEGRO | H2: Formula (calculado) | I2: VERDE | J2: Link a otra hoja | K2: VERDE CLARO | L2: Resultado / output
A4: Concepto: tomamos el spot price como dado y resolvemos hacia atras los inputs implicitos.
B5: Ayuda a contrastar tu tesis con lo que el mercado ya esta descontando.
A7: 1. ESTADO DE MERCADO + CASO BASE (links)
B8: Spot price ($) | D8: =Hipotesis!D55 -> 77.11
B9: Acciones diluidas (k) | D9: =Hipotesis!D46 -> 2071391
B10: Market Cap ($M) | D10: =D8*D9/1000 -> 159724.96
B11: (+) LT Debt | D11: =Hipotesis!D51 -> 10514
B12: (-) Cash + ST inv | D12: =-Hipotesis!D49-Hipotesis!D50 -> -6091
B13: (-) Equity stakes (Aurora, Grab, Didi, Lucid, etc.) | D13: =-Hipotesis!D52 -> -8109
B14: (-) Equity method investments | D14: =-Hipotesis!D53 -> -268
B15: (+) NCI | D15: =Hipotesis!D54 -> 1061
B16: OPERATING EV (lo que el mercado paga por las operaciones) | D16: =SUM(D10:D15) -> 156831.96
A18: Parametros del caso base (Hipotesis):
B19: WACC | D19: =Hipotesis!D14 -> 0.104564
B20: TGR (g) base | D20: =Hipotesis!D15 -> 0.025
B21: Tipo impositivo (T) | D21: =Hipotesis!D10 -> 0.22
